<robot name="onshape">
<link name="base">
<visual>
<origin xyz="-0.52272081807819015253 -0.73641766470874725492 -0.2599892390752428506" rpy="-1.5386514143497226036e-08 -4.136606507362698783e-08 2.4434609583254234266" />
<geometry>
<mesh filename="package:///motor.stl"/>
</geometry>
<material name="motor_material">
<color rgba="0.64705882352941179736 0.64705882352941179736 0.64705882352941179736 1.0"/>
</material>
</visual>
<collision>
<origin xyz="-0.52272081807819015253 -0.73641766470874725492 -0.2599892390752428506" rpy="-1.5386514143497226036e-08 -4.136606507362698783e-08 2.4434609583254234266" />
<geometry>
<mesh filename="package:///motor.stl"/>
</geometry>
</collision>
<visual>
<origin xyz="-1.2172139821489849076 -0.32774477465462825698 -0.25998920825331905959" rpy="1.5386514121793446057e-08 4.1366065437873402999e-08 -0.69813169526436968937" />
<geometry>
<mesh filename="package:///motor.stl"/>
</geometry>
<material name="motor_material">
<color rgba="0.64705882352941179736 0.64705882352941179736 0.64705882352941179736 1.0"/>
</material>
</visual>
<collision>
<origin xyz="-1.2172139821489849076 -0.32774477465462825698 -0.25998920825331905959" rpy="1.5386514121793446057e-08 4.1366065437873402999e-08 -0.69813169526436968937" />
<geometry>
<mesh filename="package:///motor.stl"/>
</geometry>
</collision>
<visual>
<origin xyz="0.097697778699967541272 0.0029684352226908017336 -0.25998922422417936051" rpy="-1.5386514143497249198e-08 -4.1366065073626974595e-08 2.4434609583254229825" />
<geometry>
<mesh filename="package:///motor.stl"/>
</geometry>
<material name="motor_material">
<color rgba="0.64705882352941179736 0.64705882352941179736 0.64705882352941179736 1.0"/>
</material>
</visual>
<collision>
<origin xyz="0.097697778699967541272 0.0029684352226908017336 -0.25998922422417936051" rpy="-1.5386514143497249198e-08 -4.1366065073626974595e-08 2.4434609583254229825" />
<geometry>
<mesh filename="package:///motor.stl"/>
</geometry>
</collision>
<visual>
<origin xyz="-0.77661850693285938707 -0.33686214394097313551 -0.28437321820730343536" rpy="-1.5707963114083824951 4.136606507362698783e-08 -0.69813169526436991141" />
<geometry>
<mesh filename="package:///baseplate.stl"/>
</geometry>
<material name="baseplate_material">
<color rgba="0.43921568627450979783 0.47450980392156860699 0.50196078431372548323 1.0"/>
</material>
</visual>
<collision>
<origin xyz="-0.77661850693285938707 -0.33686214394097313551 -0.28437321820730343536" rpy="-1.5707963114083824951 4.136606507362698783e-08 -0.69813169526436991141" />
<geometry>
<mesh filename="package:///baseplate.stl"/>
</geometry>
</collision>
<visual>
<origin xyz="-0.59679538537082710281 0.41164132527681007723 -0.25998919340225568053" rpy="1.5386514143497222728e-08 4.1366065073627034152e-08 -0.6981316952643703555" />
<geometry>
<mesh filename="package:///motor.stl"/>
</geometry>
<material name="motor_material">
<color rgba="0.64705882352941179736 0.64705882352941179736 0.64705882352941179736 1.0"/>
</material>
</visual>
<collision>
<origin xyz="-0.59679538537082710281 0.41164132527681007723 -0.25998919340225568053" rpy="1.5386514143497222728e-08 4.1366065073627034152e-08 -0.6981316952643703555" />
<geometry>
<mesh filename="package:///motor.stl"/>
</geometry>
</collision>
<inertial>
<origin xyz="-0.55889969120758586918 -0.1628107152871994534 -0.43853106493353521955" rpy="0 0 0"/>
<mass value="1406.2088699182118035" />
<inertia ixx="228.28431559539390605" ixy="23.919670888678130183"  ixz="0.86795731984523216695" iyy="236.65437763186523057" iyz="-0.75828706724099870229" izz="407.15709149261124367" />
</inertial>
</link>

<link name="segment1">
<visual>
<origin xyz="-0.38910259999999918801 -0.15773400000000015186 -0.27543125000000101554" rpy="1.5707963267948987784 -1.570796326794896336 0" />
<geometry>
<mesh filename="package:///motor.stl"/>
</geometry>
<material name="motor_material">
<color rgba="0.64705882352941179736 0.64705882352941179736 0.64705882352941179736 1.0"/>
</material>
</visual>
<collision>
<origin xyz="-0.38910259999999918801 -0.15773400000000015186 -0.27543125000000101554" rpy="1.5707963267948987784 -1.570796326794896336 0" />
<geometry>
<mesh filename="package:///motor.stl"/>
</geometry>
</collision>
<visual>
<origin xyz="0.03850640000000016272 -0.088899999999999992917 -0.45923199999999997356" rpy="-3.6532218045978013582e-24 4.3108007020244402341e-25 -4.6221585178814559068e-17" />
<geometry>
<mesh filename="package:///legjointconnector1.stl"/>
</geometry>
<material name="legjointconnector1_material">
<color rgba="0.2313725490196078538 0.38039215686274507888 0.7058823529411765163 1.0"/>
</material>
</visual>
<collision>
<origin xyz="0.03850640000000016272 -0.088899999999999992917 -0.45923199999999997356" rpy="-3.6532218045978013582e-24 4.3108007020244402341e-25 -4.6221585178814559068e-17" />
<geometry>
<mesh filename="package:///legjointconnector1.stl"/>
</geometry>
</collision>
<inertial>
<origin xyz="-0.40919518440973640105 -0.02950843765102784122 -0.22545957775453864813" rpy="0 0 0"/>
<mass value="188.73631876709129074" />
<inertia ixx="4.6537577933984133338" ixy="-0.25943209440127823484"  ixz="0.036542406653591145982" iyy="5.7446693413348537405" iyz="0.16661863662345741122" izz="4.0892590965830653005" />
</inertial>
</link>

<link name="legjointconnector2">
<visual>
<origin xyz="0.070232476114742814488 -0.16024474380306913401 -0.43052999999999974623" rpy="1.570796326794896558 3.9652528881562944723e-18 -1.0263196134749687987e-16" />
<geometry>
<mesh filename="package:///legjointconnector2.stl"/>
</geometry>
<material name="legjointconnector2_material">
<color rgba="0.76862745098039220171 0.88627450980392152857 0.95294117647058818044 1.0"/>
</material>
</visual>
<collision>
<origin xyz="0.070232476114742814488 -0.16024474380306913401 -0.43052999999999974623" rpy="1.570796326794896558 3.9652528881562944723e-18 -1.0263196134749687987e-16" />
<geometry>
<mesh filename="package:///legjointconnector2.stl"/>
</geometry>
</collision>
<inertial>
<origin xyz="0.061843433631572700127 -0.16731335776010902716 -0.22965309411969186959" rpy="0 0 0"/>
<mass value="33.700879238921572778" />
<inertia ixx="1.8183343062068182405" ixy="0.17203321537692853327"  ixz="0.00026994432076568640813" iyy="1.723138564380447324" iyz="-0.00019728284462278134186" izz="0.83789669946887102014" />
</inertial>
</link>

<link name="segment3">
<visual>
<origin xyz="-0.60765120142243822521 -0.063499999999997114308 -0.4754880000000201723" rpy="7.2929069426136926163e-14 -3.6662788731548262329e-14 -3.6929929517257947923e-16" />
<geometry>
<mesh filename="package:///legjointconnector3.stl"/>
</geometry>
<material name="legjointconnector3_material">
<color rgba="0.81176470588235294379 0.85882352941176465233 0.89803921568627453897 1.0"/>
</material>
</visual>
<collision>
<origin xyz="-0.60765120142243822521 -0.063499999999997114308 -0.4754880000000201723" rpy="7.2929069426136926163e-14 -3.6662788731548262329e-14 -3.6929929517257947923e-16" />
<geometry>
<mesh filename="package:///legjointconnector3.stl"/>
</geometry>
</collision>
<visual>
<origin xyz="-1.0160711528448753693 0.066675000000001150013 -0.11861800000003158706" rpy="-7.3444738787720256057e-14 3.5909276497474663221e-14 3.141592653589793116" />
<geometry>
<mesh filename="package:///motor.stl"/>
</geometry>
<material name="motor_material">
<color rgba="0.64705882352941179736 0.64705882352941179736 0.64705882352941179736 1.0"/>
</material>
</visual>
<collision>
<origin xyz="-1.0160711528448753693 0.066675000000001150013 -0.11861800000003158706" rpy="-7.3444738787720256057e-14 3.5909276497474663221e-14 3.141592653589793116" />
<geometry>
<mesh filename="package:///motor.stl"/>
</geometry>
</collision>
<visual>
<origin xyz="-0.14843125000000001457 -0.066674999999999928768 -0.11861800000000000122" rpy="-1.9158494772844842546e-17 -5.2206511014197193946e-17 -4.5843758117146776503e-17" />
<geometry>
<mesh filename="package:///motor.stl"/>
</geometry>
<material name="motor_material">
<color rgba="0.64705882352941179736 0.64705882352941179736 0.64705882352941179736 1.0"/>
</material>
</visual>
<collision>
<origin xyz="-0.14843125000000001457 -0.066674999999999928768 -0.11861800000000000122" rpy="-1.9158494772844842546e-17 -5.2206511014197193946e-17 -4.5843758117146776503e-17" />
<geometry>
<mesh filename="package:///motor.stl"/>
</geometry>
</collision>
<inertial>
<origin xyz="-0.58225120142243658172 0.029032930571646964335 -0.2417833928966994228" rpy="0 0 0"/>
<mass value="415.11154881410027429" />
<inertia ixx="7.860290604406653614" ixy="5.6621374255882983562e-13"  ixz="-2.3259172365897029522e-12" iyy="82.893177179420320044" iyz="0.12274391499318063059" izz="79.382284917831896109" />
</inertial>
</link>

<link name="legjointconnector4">
<visual>
<origin xyz="0.06695440000000019154 0.088899999999999868017 -0.38290500000000005087" rpy="3.141592653589793116 -2.6559495409579760984e-16 5.1658651671119238197e-17" />
<geometry>
<mesh filename="package:///legjointconnector4.stl"/>
</geometry>
<material name="legjointconnector4_material">
<color rgba="0.49803921568627451677 0.49803921568627451677 0.49803921568627451677 1.0"/>
</material>
</visual>
<collision>
<origin xyz="0.06695440000000019154 0.088899999999999868017 -0.38290500000000005087" rpy="3.141592653589793116 -2.6559495409579760984e-16 5.1658651671119238197e-17" />
<geometry>
<mesh filename="package:///legjointconnector4.stl"/>
</geometry>
</collision>
<inertial>
<origin xyz="-0.45997164835704523744 -0.0069451045546922718366 -0.22961600000000070843" rpy="0 0 0"/>
<mass value="114.50446623722325512" />
<inertia ixx="2.1154846818863153324" ixy="-0.35839006867214406871"  ixz="4.2402368911379022517e-14" iyy="9.3487420780648040619" iyz="-3.3518134351135829548e-16" izz="7.9984733077604719398" />
</inertial>
</link>

<joint name="BL_J4" type="revolute">
<origin xyz="-1.1645024028448791586 3.3306690738754696213e-16 -3.7359004778636517585e-14" rpy="7.2159191514795347321e-14 -3.8605192353852867702e-14 9.6550876637817448444e-15" />
<parent link="segment3" />
<child link="legjointconnector4" />
<axis xyz="0 0 1"/>
<limit effort="1" velocity="20" lower="-0.34906585039886589561" upper="1.0471975511965976313"/>
<joint_properties friction="0.0"/>
</joint>

<joint name="BL_J3" type="revolute">
<origin xyz="0.20990559999999991447 -0.25054559999999986841 2.2204460492503130808e-16" rpy="-7.1969438406019748775e-14 3.7780358523688956078e-14 -3.1415926535897917837" />
<parent link="legjointconnector2" />
<child link="segment3" />
<axis xyz="0 0 1"/>
<limit effort="1" velocity="20" lower="-0.34906585039886589561" upper="1.0471975511965976313"/>
<joint_properties friction="0.0"/>
</joint>

<joint name="BL_J2" type="revolute">
<origin xyz="-0.4557775999999992278 -0.27635200000000270659 -0.12700000000000088995" rpy="-1.5707963267949023312 0.52359877559829381966 3.1415926535897895633" />
<parent link="segment1" />
<child link="legjointconnector2" />
<axis xyz="0 0 1"/>
<limit effort="1" velocity="20" lower="-0.52359877559829881566" upper="1.3962634015954635824"/>
<joint_properties friction="0.0"/>
</joint>

<joint name="BL_J1" type="revolute">
<origin xyz="-0.67928361386142521727 -0.69208391498186450086 -0.14137123396112205587" rpy="4.1366065074091267764e-08 -1.5386514204730299893e-08 0.87266463153054429913" />
<parent link="base" />
<child link="segment1" />
<axis xyz="0 0 1"/>
<limit effort="1" velocity="20" lower="0" upper="0.87266462599716476678"/>
<joint_properties friction="0.0"/>
</joint>

<link name="segment1inverse">
<visual>
<origin xyz="-0.52245259999999060785 0.15773399999999815346 -0.27543125000000223679" rpy="-1.570796326794896336 -1.5707963267948947816 0" />
<geometry>
<mesh filename="package:///motor.stl"/>
</geometry>
<material name="motor_material">
<color rgba="0.64705882352941179736 0.64705882352941179736 0.64705882352941179736 1.0"/>
</material>
</visual>
<collision>
<origin xyz="-0.52245259999999060785 0.15773399999999815346 -0.27543125000000223679" rpy="-1.570796326794896336 -1.5707963267948947816 0" />
<geometry>
<mesh filename="package:///motor.stl"/>
</geometry>
</collision>
<visual>
<origin xyz="0.038506400000000273742 -0.088899999999999979039 -0.45923199999999986254" rpy="-3.0484408739285509893e-24 4.8496501765435602034e-24 -3.2103616655347827733e-17" />
<geometry>
<mesh filename="package:///legjointconnector1.stl"/>
</geometry>
<material name="legjointconnector1_material">
<color rgba="0.2313725490196078538 0.38039215686274507888 0.7058823529411765163 1.0"/>
</material>
</visual>
<collision>
<origin xyz="0.038506400000000273742 -0.088899999999999979039 -0.45923199999999986254" rpy="-3.0484408739285509893e-24 4.8496501765435602034e-24 -3.2103616655347827733e-17" />
<geometry>
<mesh filename="package:///legjointconnector1.stl"/>
</geometry>
</collision>
<inertial>
<origin xyz="-0.40919518440972968421 0.029508437651027417947 -0.22545957775453931426" rpy="0 0 0"/>
<mass value="188.73631876709129074" />
<inertia ixx="4.6537577933983200751" ixy="0.25943209440126868692"  ixz="0.036542406653598140387" iyy="5.7446693413346858748" iyz="-0.16661863662345188786" izz="4.0892590965829889171" />
</inertial>
</link>

<link name="legjointconnector2_2">
<visual>
<origin xyz="0.070232476114742592443 0.16024474380306930055 -0.028702000000000005286" rpy="-1.570796326794896558 -6.3637176857834707342e-17 4.1494855068624425916e-17" />
<geometry>
<mesh filename="package:///legjointconnector2.stl"/>
</geometry>
<material name="legjointconnector2_material">
<color rgba="0.76862745098039220171 0.88627450980392152857 0.95294117647058818044 1.0"/>
</material>
</visual>
<collision>
<origin xyz="0.070232476114742592443 0.16024474380306930055 -0.028702000000000005286" rpy="-1.570796326794896558 -6.3637176857834707342e-17 4.1494855068624425916e-17" />
<geometry>
<mesh filename="package:///legjointconnector2.stl"/>
</geometry>
</collision>
<inertial>
<origin xyz="0.061843433631572478082 0.16731335776010916594 -0.22957890588030788193" rpy="0 0 0"/>
<mass value="33.700879238921572778" />
<inertia ixx="1.8183343062068186846" ixy="-0.17203321537692883858"  ixz="-0.00026994432076558373419" iyy="1.7231385643804477681" iyz="-0.00019728284462272133127" izz="0.83789669946887102014" />
</inertial>
</link>

<link name="segment3_2">
<visual>
<origin xyz="-0.55685120142245381203 0.063500000000000000888 -0.47548799999999941113" rpy="5.1252813749132234066e-16 -4.5642826981277378091e-17 3.141592653589793116" />
<geometry>
<mesh filename="package:///legjointconnector3.stl"/>
</geometry>
<material name="legjointconnector3_material">
<color rgba="0.81176470588235294379 0.85882352941176465233 0.89803921568627453897 1.0"/>
</material>
</visual>
<collision>
<origin xyz="-0.55685120142245381203 0.063500000000000000888 -0.47548799999999941113" rpy="5.1252813749132234066e-16 -4.5642826981277378091e-17 3.141592653589793116" />
<geometry>
<mesh filename="package:///legjointconnector3.stl"/>
</geometry>
</collision>
<visual>
<origin xyz="-0.14843124999999979252 -0.06667500000000003979 -0.11861799999999989019" rpy="-5.0285340606972555061e-18 2.1890916200357650122e-17 -2.6754563663643354839e-17" />
<geometry>
<mesh filename="package:///motor.stl"/>
</geometry>
<material name="motor_material">
<color rgba="0.64705882352941179736 0.64705882352941179736 0.64705882352941179736 1.0"/>
</material>
</visual>
<collision>
<origin xyz="-0.14843124999999979252 -0.06667500000000003979 -0.11861799999999989019" rpy="-5.0285340606972555061e-18 2.1890916200357650122e-17 -2.6754563663643354839e-17" />
<geometry>
<mesh filename="package:///motor.stl"/>
</geometry>
</collision>
<visual>
<origin xyz="-1.0160711528449279939 0.066675000000000816947 -0.11861799999999877997" rpy="8.2998597554373513691e-16 -9.4290892471675295262e-16 -3.1415926535897926719" />
<geometry>
<mesh filename="package:///motor.stl"/>
</geometry>
<material name="motor_material">
<color rgba="0.64705882352941179736 0.64705882352941179736 0.64705882352941179736 1.0"/>
</material>
</visual>
<collision>
<origin xyz="-1.0160711528449279939 0.066675000000000816947 -0.11861799999999877997" rpy="8.2998597554373513691e-16 -9.4290892471675295262e-16 -3.1415926535897926719" />
<geometry>
<mesh filename="package:///motor.stl"/>
</geometry>
</collision>
<inertial>
<origin xyz="-0.58225120142246111765 -0.029032930571645812479 -0.24178339289668338008" rpy="0 0 0"/>
<mass value="415.11154881410027429" />
<inertia ixx="7.8602906044070977032" ixy="1.0969003483296546619e-13"  ixz="-4.174438572590588592e-14" iyy="82.893177179428192858" iyz="-0.12274391499226865176" izz="79.382284917839598393" />
</inertial>
</link>

<link name="legjointconnector4_2">
<visual>
<origin xyz="0.066954399999999303361 -0.088899999999999868017 -0.076326999999999922686" rpy="5.903769525121679579e-18 -5.2427714696408834966e-17 1.3882424487686963416e-17" />
<geometry>
<mesh filename="package:///legjointconnector4.stl"/>
</geometry>
<material name="legjointconnector4_material">
<color rgba="0.49803921568627451677 0.49803921568627451677 0.49803921568627451677 1.0"/>
</material>
</visual>
<collision>
<origin xyz="0.066954399999999303361 -0.088899999999999868017 -0.076326999999999922686" rpy="5.903769525121679579e-18 -5.2427714696408834966e-17 1.3882424487686963416e-17" />
<geometry>
<mesh filename="package:///legjointconnector4.stl"/>
</geometry>
</collision>
<inertial>
<origin xyz="-0.45997164835704607011 0.0069451045546922059171 -0.22961599999999945942" rpy="0 0 0"/>
<mass value="114.50446623722325512" />
<inertia ixx="2.1154846818863153324" ixy="0.3583900686721445128"  ixz="-4.3384933615602907116e-14" iyy="9.3487420780648005092" iyz="2.3962744477999091129e-16" izz="7.9984733077604719398" />
</inertial>
</link>

<joint name="FL_J4" type="revolute">
<origin xyz="-1.1645024028449126874 -4.4408920985006261617e-16 1.8873791418627661187e-15" rpy="-1.1469567991054151564e-15 6.4836619306514026563e-16 2.3592702349518586125e-16" />
<parent link="segment3_2" />
<child link="legjointconnector4_2" />
<axis xyz="0 0 1"/>
<limit effort="1" velocity="20" lower="-1.0471975511965976313" upper="0.34906585039886589561"/>
<joint_properties friction="0.0"/>
</joint>

<joint name="FL_J3" type="revolute">
<origin xyz="0.20990560000000013652 0.25054559999999992392 -1.1102230246251565404e-16" rpy="3.3343912457666189774e-16 -4.6147739789338615047e-15 3.1415926535897922278" />
<parent link="legjointconnector2_2" />
<child link="segment3_2" />
<axis xyz="0 0 1"/>
<limit effort="1" velocity="20" lower="-1.0471975511965976313" upper="0.34906585039886589561"/>
<joint_properties friction="0.0"/>
</joint>

<joint name="FL_J2" type="revolute">
<origin xyz="-0.45577759999999967189 0.27635199999999893183 -0.12700000000000119527" rpy="1.5707963267948972241 0.52359877559828815752 -3.1415926535897926719" />
<parent link="segment1inverse" />
<child link="legjointconnector2_2" />
<axis xyz="0 0 1"/>
<limit effort="1" velocity="20" lower="-1.3962634015954635824" upper="0.52359877559829881566"/>
<joint_properties friction="0.0"/>
</joint>

<joint name="FL_J1" type="revolute">
<origin xyz="-1.060651181194484094 -0.3720785334857630855 -0.14137121336743724287" rpy="4.13660654493550868e-08 -1.5386514143357501996e-08 0.87266463153052498125" />
<parent link="base" />
<child link="segment1inverse" />
<axis xyz="0 0 1"/>
<limit effort="1" velocity="20" lower="-0.87266462599716476678" upper="0"/>
<joint_properties friction="0.0"/>
</joint>

<link name="segment1_2">
<visual>
<origin xyz="-0.38910260000000029823 -0.15773399999999537791 -0.27543124999999801794" rpy="1.5707963267948961139 -1.5707963267948752417 0" />
<geometry>
<mesh filename="package:///motor.stl"/>
</geometry>
<material name="motor_material">
<color rgba="0.64705882352941179736 0.64705882352941179736 0.64705882352941179736 1.0"/>
</material>
</visual>
<collision>
<origin xyz="-0.38910260000000029823 -0.15773399999999537791 -0.27543124999999801794" rpy="1.5707963267948961139 -1.5707963267948752417 0" />
<geometry>
<mesh filename="package:///motor.stl"/>
</geometry>
</collision>
<visual>
<origin xyz="0.038506400000000273742 -0.088899999999999868017 -0.45923199999999986254" rpy="-3.5692679270799559433e-24 1.7677065874689904192e-24 -6.7208852565116396272e-17" />
<geometry>
<mesh filename="package:///legjointconnector1.stl"/>
</geometry>
<material name="legjointconnector1_material">
<color rgba="0.2313725490196078538 0.38039215686274507888 0.7058823529411765163 1.0"/>
</material>
</visual>
<collision>
<origin xyz="0.038506400000000273742 -0.088899999999999868017 -0.45923199999999986254" rpy="-3.5692679270799559433e-24 1.7677065874689904192e-24 -6.7208852565116396272e-17" />
<geometry>
<mesh filename="package:///legjointconnector1.stl"/>
</geometry>
</collision>
<inertial>
<origin xyz="-0.40919518440973634554 -0.029508437651025228726 -0.22545957775453764893" rpy="0 0 0"/>
<mass value="188.73631876709129074" />
<inertia ixx="4.6537577933983023115" ixy="-0.25943209440126463461"  ixz="0.036542406653627776403" iyy="5.7446693413348377533" iyz="0.16661863662341358516" izz="4.089259096583027997" />
</inertial>
</link>

<link name="legjointconnector2_3">
<visual>
<origin xyz="0.070232476114742814488 -0.16024474380306935606 -0.43053000000000002379" rpy="1.570796326794896558 1.9178368029502426979e-17 -1.019419865797463865e-17" />
<geometry>
<mesh filename="package:///legjointconnector2.stl"/>
</geometry>
<material name="legjointconnector2_material">
<color rgba="0.76862745098039220171 0.88627450980392152857 0.95294117647058818044 1.0"/>
</material>
</visual>
<collision>
<origin xyz="0.070232476114742814488 -0.16024474380306935606 -0.43053000000000002379" rpy="1.570796326794896558 1.9178368029502426979e-17 -1.019419865797463865e-17" />
<geometry>
<mesh filename="package:///legjointconnector2.stl"/>
</geometry>
</collision>
<inertial>
<origin xyz="0.061843433631572651554 -0.16731335776010922145 -0.22965309411969203612" rpy="0 0 0"/>
<mass value="33.700879238921572778" />
<inertia ixx="1.8183343062068182405" ixy="0.17203321537692881082"  ixz="0.00026994432076546295406" iyy="1.723138564380447324" iyz="-0.0001972828446227085919" izz="0.83789669946887190832" />
</inertial>
</link>

<link name="segment3_3">
<visual>
<origin xyz="-0.60765120142245476753 -0.063499999999999667821 -0.47548800000000335242" rpy="1.3051464295867114026e-15 1.2007908984991907663e-16 -9.8363707927120520457e-19" />
<geometry>
<mesh filename="package:///legjointconnector3.stl"/>
</geometry>
<material name="legjointconnector3_material">
<color rgba="0.81176470588235294379 0.85882352941176465233 0.89803921568627453897 1.0"/>
</material>
</visual>
<collision>
<origin xyz="-0.60765120142245476753 -0.063499999999999667821 -0.47548800000000335242" rpy="1.3051464295867114026e-15 1.2007908984991907663e-16 -9.8363707927120520457e-19" />
<geometry>
<mesh filename="package:///legjointconnector3.stl"/>
</geometry>
</collision>
<visual>
<origin xyz="-1.0160711528449013485 0.066674999999999567946 -0.11861800000000011224" rpy="-2.098128126056238583e-15 -9.6327213513160254065e-17 3.141592653589793116" />
<geometry>
<mesh filename="package:///motor.stl"/>
</geometry>
<material name="motor_material">
<color rgba="0.64705882352941179736 0.64705882352941179736 0.64705882352941179736 1.0"/>
</material>
</visual>
<collision>
<origin xyz="-1.0160711528449013485 0.066674999999999567946 -0.11861800000000011224" rpy="-2.098128126056238583e-15 -9.6327213513160254065e-17 3.141592653589793116" />
<geometry>
<mesh filename="package:///motor.stl"/>
</geometry>
</collision>
<visual>
<origin xyz="-0.14843124999999979252 -0.06667500000000003979 -0.11861800000000011224" rpy="-1.9356871074527568652e-17 -3.0980219178960907332e-17 -1.1090481756904428507e-17" />
<geometry>
<mesh filename="package:///motor.stl"/>
</geometry>
<material name="motor_material">
<color rgba="0.64705882352941179736 0.64705882352941179736 0.64705882352941179736 1.0"/>
</material>
</visual>
<collision>
<origin xyz="-0.14843124999999979252 -0.06667500000000003979 -0.11861800000000011224" rpy="-1.9356871074527568652e-17 -3.0980219178960907332e-17 -1.1090481756904428507e-17" />
<geometry>
<mesh filename="package:///motor.stl"/>
</geometry>
</collision>
<inertial>
<origin xyz="-0.58225120142245145871 0.029032930571645722273 -0.24178339289668410172" rpy="0 0 0"/>
<mass value="415.11154881410027429" />
<inertia ixx="7.8602906044069280611" ixy="3.2862601528904633597e-14"  ixz="3.2529534621517086634e-14" iyy="82.893177179424384349" iyz="0.12274391499229075908" izz="79.382284917836074101" />
</inertial>
</link>

<link name="legjointconnector4_3">
<visual>
<origin xyz="0.06695440000000019154 0.08890000000000003455 -0.38290499999999977332" rpy="-3.141592653589793116 -2.0849098636161692206e-16 4.310488299411928224e-17" />
<geometry>
<mesh filename="package:///legjointconnector4.stl"/>
</geometry>
<material name="legjointconnector4_material">
<color rgba="0.49803921568627451677 0.49803921568627451677 0.49803921568627451677 1.0"/>
</material>
</visual>
<collision>
<origin xyz="0.06695440000000019154 0.08890000000000003455 -0.38290499999999977332" rpy="-3.141592653589793116 -2.0849098636161692206e-16 4.310488299411928224e-17" />
<geometry>
<mesh filename="package:///legjointconnector4.stl"/>
</geometry>
</collision>
<inertial>
<origin xyz="-0.45997164835704507091 -0.0069451045546920775475 -0.2296160000000003476" rpy="0 0 0"/>
<mass value="114.50446623722325512" />
<inertia ixx="2.1154846818863144442" ixy="-0.35839006867214345808"  ixz="4.3219090800601803662e-14" iyy="9.3487420780648005092" iyz="-8.8936560954172624083e-17" izz="7.9984733077604737161" />
</inertial>
</link>

<joint name="FR_J4" type="revolute">
<origin xyz="-1.1645024028448989206 -1.9428902930940239457e-16 9.9920072216264088638e-16" rpy="2.0702645687492304713e-15 -1.2750068319148383268e-14 -1.7893969234326057185e-16" />
<parent link="segment3_3" />
<child link="legjointconnector4_3" />
<axis xyz="0 0 1"/>
<limit effort="1" velocity="20" lower="-0.34906585039886589561" upper="1.0471975511965976313"/>
<joint_properties friction="0.0"/>
</joint>

<joint name="FR_J3" type="revolute">
<origin xyz="0.20990560000000024754 -0.25054560000000014597 2.2204460492503130808e-16" rpy="-1.8985674999768793355e-15 1.23596449809788972e-14 -3.141592653589763362" />
<parent link="legjointconnector2_3" />
<child link="segment3_3" />
<axis xyz="0 0 1"/>
<limit effort="1" velocity="20" lower="-0.34906585039886589561" upper="1.0471975511965976313"/>
<joint_properties friction="0.0"/>
</joint>

<joint name="FR_J2" type="revolute">
<origin xyz="-0.45577759999999989393 -0.27635199999999915388 -0.12699999999999947442" rpy="-1.5707963267948974462 0.52359877559829615112 3.1415926535897762406" />
<parent link="segment1_2" />
<child link="legjointconnector2_3" />
<axis xyz="0 0 1"/>
<limit effort="1" velocity="20" lower="-0.52359877559829881566" upper="1.3962634015954635824"/>
<joint_properties friction="0.0"/>
</joint>

<joint name="FR_J1" type="revolute">
<origin xyz="-0.44023258441632540094 0.3673075664456756928 -0.14137119851637669488" rpy="-4.1366039038186796774e-08 1.538652296404905063e-08 -2.2689280220592675796" />
<parent link="base" />
<child link="segment1_2" />
<axis xyz="0 0 1"/>
<limit effort="1" velocity="20" lower="0" upper="0.87266462599716476678"/>
<joint_properties friction="0.0"/>
</joint>

<link name="segment1inverse_2">
<visual>
<origin xyz="-0.52245259999999893452 0.15773399999999968002 -0.27543125000000046043" rpy="-1.57079632679489678 -1.5707963267948961139 0" />
<geometry>
<mesh filename="package:///motor.stl"/>
</geometry>
<material name="motor_material">
<color rgba="0.64705882352941179736 0.64705882352941179736 0.64705882352941179736 1.0"/>
</material>
</visual>
<collision>
<origin xyz="-0.52245259999999893452 0.15773399999999968002 -0.27543125000000046043" rpy="-1.57079632679489678 -1.5707963267948961139 0" />
<geometry>
<mesh filename="package:///motor.stl"/>
</geometry>
</collision>
<visual>
<origin xyz="0.038506400000000273742 -0.088899999999999937406 -0.45923199999999991805" rpy="-1.8786679503594021808e-24 -7.54389899819249155e-25 3.5630072008523322586e-17" />
<geometry>
<mesh filename="package:///legjointconnector1.stl"/>
</geometry>
<material name="legjointconnector1_material">
<color rgba="0.2313725490196078538 0.38039215686274507888 0.7058823529411765163 1.0"/>
</material>
</visual>
<collision>
<origin xyz="0.038506400000000273742 -0.088899999999999937406 -0.45923199999999991805" rpy="-1.8786679503594021808e-24 -7.54389899819249155e-25 3.5630072008523322586e-17" />
<geometry>
<mesh filename="package:///legjointconnector1.stl"/>
</geometry>
</collision>
<inertial>
<origin xyz="-0.40919518440973567941 0.029508437651028229798 -0.22545957775453878691" rpy="0 0 0"/>
<mass value="188.73631876709129074" />
<inertia ixx="4.6537577933983609313" ixy="0.25943209440128561782"  ixz="0.036542406653597252209" iyy="5.7446693413348075552" iyz="-0.1666186366234468641" izz="4.089259096583052866" />
</inertial>
</link>

<link name="legjointconnector2_4">
<visual>
<origin xyz="0.070232476114742814488 0.16024474380306930055 -0.028702000000000060798" rpy="-1.570796326794896558 5.3231344441698284403e-18 1.4217869150613816996e-17" />
<geometry>
<mesh filename="package:///legjointconnector2.stl"/>
</geometry>
<material name="legjointconnector2_material">
<color rgba="0.76862745098039220171 0.88627450980392152857 0.95294117647058818044 1.0"/>
</material>
</visual>
<collision>
<origin xyz="0.070232476114742814488 0.16024474380306930055 -0.028702000000000060798" rpy="-1.570796326794896558 5.3231344441698284403e-18 1.4217869150613816996e-17" />
<geometry>
<mesh filename="package:///legjointconnector2.stl"/>
</geometry>
</collision>
<inertial>
<origin xyz="0.061843433631572665432 0.16731335776010913818 -0.22957890588030804846" rpy="0 0 0"/>
<mass value="33.700879238921572778" />
<inertia ixx="1.8183343062068186846" ixy="-0.1720332153769286998"  ixz="-0.00026994432076554725078" iyy="1.7231385643804477681" iyz="-0.00019728284462267441242" izz="0.83789669946887190832" />
</inertial>
</link>

<link name="segment3_4">
<visual>
<origin xyz="-0.55685120142244548536 0.063499999999996836753 -0.47548799999999902255" rpy="2.1027972864526789431e-15 6.5512768557325741053e-16 -3.1415926535897913396" />
<geometry>
<mesh filename="package:///legjointconnector3.stl"/>
</geometry>
<material name="legjointconnector3_material">
<color rgba="0.81176470588235294379 0.85882352941176465233 0.89803921568627453897 1.0"/>
</material>
</visual>
<collision>
<origin xyz="-0.55685120142244548536 0.063499999999996836753 -0.47548799999999902255" rpy="2.1027972864526789431e-15 6.5512768557325741053e-16 -3.1415926535897913396" />
<geometry>
<mesh filename="package:///legjointconnector3.stl"/>
</geometry>
</collision>
<visual>
<origin xyz="-0.14843125000000012559 -0.066675000000000067546 -0.11861799999999995958" rpy="-3.7548236879268851218e-17 4.3414288532653718895e-17 7.8865983882545317456e-18" />
<geometry>
<mesh filename="package:///motor.stl"/>
</geometry>
<material name="motor_material">
<color rgba="0.64705882352941179736 0.64705882352941179736 0.64705882352941179736 1.0"/>
</material>
</visual>
<collision>
<origin xyz="-0.14843125000000012559 -0.066675000000000067546 -0.11861799999999995958" rpy="-3.7548236879268851218e-17 4.3414288532653718895e-17 7.8865983882545317456e-18" />
<geometry>
<mesh filename="package:///motor.stl"/>
</geometry>
</collision>
<visual>
<origin xyz="-1.0160711528448893581 0.066674999999995737676 -0.11861799999999989019" rpy="2.1306069251110395535e-15 6.7877146540478259127e-16 -3.1415926535897908956" />
<geometry>
<mesh filename="package:///motor.stl"/>
</geometry>
<material name="motor_material">
<color rgba="0.64705882352941179736 0.64705882352941179736 0.64705882352941179736 1.0"/>
</material>
</visual>
<collision>
<origin xyz="-1.0160711528448893581 0.066674999999995737676 -0.11861799999999989019" rpy="2.1306069251110395535e-15 6.7877146540478259127e-16 -3.1415926535897908956" />
<geometry>
<mesh filename="package:///motor.stl"/>
</geometry>
</collision>
<inertial>
<origin xyz="-0.58225120142244468635 -0.02903293057164674576 -0.24178339289668263068" rpy="0 0 0"/>
<mass value="415.11154881410027429" />
<inertia ixx="7.8602906044068276969" ixy="-1.1790568521519162459e-13"  ixz="4.490852134608758206e-14" iyy="82.893177179421968503" iyz="-0.12274391499229607427" izz="79.382284917833970894" />
</inertial>
</link>

<link name="legjointconnector4_4">
<visual>
<origin xyz="0.066954400000000413584 -0.088899999999999979039 -0.076326999999999936564" rpy="-1.8376060247214687908e-17 -3.8018207303880034886e-17 3.1475724374566257316e-17" />
<geometry>
<mesh filename="package:///legjointconnector4.stl"/>
</geometry>
<material name="legjointconnector4_material">
<color rgba="0.49803921568627451677 0.49803921568627451677 0.49803921568627451677 1.0"/>
</material>
</visual>
<collision>
<origin xyz="0.066954400000000413584 -0.088899999999999979039 -0.076326999999999936564" rpy="-1.8376060247214687908e-17 -3.8018207303880034886e-17 3.1475724374566257316e-17" />
<geometry>
<mesh filename="package:///legjointconnector4.stl"/>
</geometry>
</collision>
<inertial>
<origin xyz="-0.45997164835704473784 0.0069451045546920827517 -0.22961599999999948718" rpy="0 0 0"/>
<mass value="114.50446623722325512" />
<inertia ixx="2.115484681886313556" ixy="0.35839006867214373564"  ixz="-4.368549154861011576e-14" iyy="9.3487420780648005092" iyz="1.6314246535086514003e-16" izz="7.9984733077604737161" />
</inertial>
</link>

<joint name="BR_J4" type="revolute">
<origin xyz="-1.1645024028448931475 -1.8873791418627661187e-15 -1.4988010832439613296e-15" rpy="-1.7655377548137906651e-15 -8.4596118181461122216e-17 2.4739660131420130417e-15" />
<parent link="segment3_4" />
<child link="legjointconnector4_4" />
<axis xyz="0 0 1"/>
<limit effort="1" velocity="20" lower="-1.0471975511965976313" upper="0.34906585039886589561"/>
<joint_properties friction="0.0"/>
</joint>

<joint name="BR_J3" type="revolute">
<origin xyz="0.20990559999999747198 0.2505455999999988137 5.8286708792820718372e-16" rpy="1.4373447656321374473e-15 4.3984744919560549052e-16 3.1415926535897922278" />
<parent link="legjointconnector2_4" />
<child link="segment3_4" />
<axis xyz="0 0 1"/>
<limit effort="1" velocity="20" lower="-1.0471975511965976313" upper="0.34906585039886589561"/>
<joint_properties friction="0.0"/>
</joint>

<joint name="BR_J2" type="revolute">
<origin xyz="-0.45577759999999967189 0.27635199999999970899 -0.12700000000000022382" rpy="1.5707963267948970021 0.52359877559830325655 -3.1415926535897926719" />
<parent link="segment1inverse_2" />
<child link="legjointconnector2_4" />
<axis xyz="0 0 1"/>
<limit effort="1" velocity="20" lower="-1.3962634015954635824" upper="0.52359877559829881566"/>
<joint_properties friction="0.0"/>
</joint>

<joint name="BR_J1" type="revolute">
<origin xyz="-0.058865017083267592857 0.04730218494957370845 -0.14137121911005823272" rpy="-4.1366065085108797363e-08 1.5386514061235917372e-08 -2.2689280220592675796" />
<parent link="base" />
<child link="segment1inverse_2" />
<axis xyz="0 0 1"/>
<limit effort="1" velocity="20" lower="-0.87266462599716476678" upper="0"/>
<joint_properties friction="0.0"/>
</joint>


</robot>
