<robot name="onshape">
<link name="segment1inverse">
<visual>
<origin xyz="-1.1005265977769753682 -0.4410712206259563839 -1.0541807331792394375" rpy="-1.5707963267948961139 -1.570796281774818004 0" />
<geometry>
<mesh filename="package:///motor.stl"/>
</geometry>
<material name="motor_material">
<color rgba="0.64705882352941179736 0.64705882352941179736 0.64705882352941179736 1.0"/>
</material>
</visual>
<collision>
<origin xyz="-1.1005265977769753682 -0.4410712206259563839 -1.0541807331792394375" rpy="-1.5707963267948961139 -1.570796281774818004 0" />
<geometry>
<mesh filename="package:///motor.stl"/>
</geometry>
</collision>
<visual>
<origin xyz="-0.53956760216484966897 -0.68770521361042902253 -1.2379815059848313652" rpy="3.8169197161100666219e-08 2.3872993578795221065e-08 3.993076537591702147e-16" />
<geometry>
<mesh filename="package:///legjointconnector1.stl"/>
</geometry>
<material name="legjointconnector1_material">
<color rgba="0.2313725490196078538 0.38039215686274507888 0.7058823529411765163 1.0"/>
</material>
</visual>
<collision>
<origin xyz="-0.53956760216484966897 -0.68770521361042902253 -1.2379815059848313652" rpy="3.8169197161100666219e-08 2.3872993578795221065e-08 3.993076537591702147e-16" />
<geometry>
<mesh filename="package:///legjointconnector1.stl"/>
</geometry>
</collision>
<inertial>
<origin xyz="-0.98726918099373883742 -0.56929678488230661682 -1.0042090685318383336" rpy="0 0 0"/>
<mass value="188.73631876709129074" />
<inertia ixx="4.6537577951431172707" ixy="0.2594320890288095427"  ixz="0.036542403079638074992" iyy="5.7446693540542224099" iyz="-0.16661857963118689718" izz="4.0892590821189100936" />
</inertial>
</link>

<link name="base">
<visual>
<origin xyz="0.64627124999999974175 0.06667500000000003979 -0.11861799999999977917" rpy="-2.026714513579360442e-24 3.6424640646368571368e-16 3.141592653589793116" />
<geometry>
<mesh filename="package:///motor.stl"/>
</geometry>
<material name="motor_material">
<color rgba="0.64705882352941179736 0.64705882352941179736 0.64705882352941179736 1.0"/>
</material>
</visual>
<collision>
<origin xyz="0.64627124999999974175 0.06667500000000003979 -0.11861799999999977917" rpy="-2.026714513579360442e-24 3.6424640646368571368e-16 3.141592653589793116" />
<geometry>
<mesh filename="package:///motor.stl"/>
</geometry>
</collision>
<visual>
<origin xyz="-0.14843124999999990354 -0.06667500000000003979 -0.11861799999999989019" rpy="-1.2820079366327203191e-24 8.7054182801646396959e-24 1.2264267336410551656e-31" />
<geometry>
<mesh filename="package:///motor.stl"/>
</geometry>
<material name="motor_material">
<color rgba="0.64705882352941179736 0.64705882352941179736 0.64705882352941179736 1.0"/>
</material>
</visual>
<collision>
<origin xyz="-0.14843124999999990354 -0.06667500000000003979 -0.11861799999999989019" rpy="-1.2820079366327203191e-24 8.7054182801646396959e-24 1.2264267336410551656e-31" />
<geometry>
<mesh filename="package:///motor.stl"/>
</geometry>
</collision>
<visual>
<origin xyz="0.64627124999999974175 1.0318749999999994316 -0.11861799999999977917" rpy="-2.5187771665064125788e-23 3.6424643293346521677e-16 3.141592653589793116" />
<geometry>
<mesh filename="package:///motor.stl"/>
</geometry>
<material name="motor_material">
<color rgba="0.64705882352941179736 0.64705882352941179736 0.64705882352941179736 1.0"/>
</material>
</visual>
<collision>
<origin xyz="0.64627124999999974175 1.0318749999999994316 -0.11861799999999977917" rpy="-2.5187771665064125788e-23 3.6424643293346521677e-16 3.141592653589793116" />
<geometry>
<mesh filename="package:///motor.stl"/>
</geometry>
</collision>
<visual>
<origin xyz="0.19494500000000014595 0.20954999999999973648 -0.14300199999999985145" rpy="-1.570796326794896558 -3.6424640646368571368e-16 -5.3869302707480762129e-24" />
<geometry>
<mesh filename="package:///baseplate.stl"/>
</geometry>
<material name="baseplate_material">
<color rgba="0.43921568627450979783 0.47450980392156860699 0.50196078431372548323 1.0"/>
</material>
</visual>
<collision>
<origin xyz="0.19494500000000014595 0.20954999999999973648 -0.14300199999999985145" rpy="-1.570796326794896558 -3.6424640646368571368e-16 -5.3869302707480762129e-24" />
<geometry>
<mesh filename="package:///baseplate.stl"/>
</geometry>
</collision>
<visual>
<origin xyz="-0.14843124999999995905 0.89852499999999968505 -0.11861800000000011224" rpy="1.1952881864215713846e-23 -3.6424638661135081519e-16 -4.9960036315952736356e-16" />
<geometry>
<mesh filename="package:///motor.stl"/>
</geometry>
<material name="motor_material">
<color rgba="0.64705882352941179736 0.64705882352941179736 0.64705882352941179736 1.0"/>
</material>
</visual>
<collision>
<origin xyz="-0.14843124999999995905 0.89852499999999968505 -0.11861800000000011224" rpy="1.1952881864215713846e-23 -3.6424638661135081519e-16 -4.9960036315952736356e-16" />
<geometry>
<mesh filename="package:///motor.stl"/>
</geometry>
</collision>
<inertial>
<origin xyz="0.249849195050954348 0.48282808420521822201 -0.29715984865985839436" rpy="0 0 0"/>
<mass value="1406.2088699182115761" />
<inertia ixx="208.18634616818542327" ixy="0.032156554270006409979"  ixz="1.1523031818811992899" iyy="256.75234696303334658" iyz="-0.02296707405691567061" izz="407.15709158865035988" />
</inertial>
</link>

<link name="segment1">
<visual>
<origin xyz="-0.38910259999999985414 -0.1577339999999998188 -0.27543124999999968328" rpy="1.570796326794896558 -1.5707963267948950037 0" />
<geometry>
<mesh filename="package:///motor.stl"/>
</geometry>
<material name="motor_material">
<color rgba="0.64705882352941179736 0.64705882352941179736 0.64705882352941179736 1.0"/>
</material>
</visual>
<collision>
<origin xyz="-0.38910259999999985414 -0.1577339999999998188 -0.27543124999999968328" rpy="1.570796326794896558 -1.5707963267948950037 0" />
<geometry>
<mesh filename="package:///motor.stl"/>
</geometry>
</collision>
<visual>
<origin xyz="0.038506400000000273742 -0.088899999999999756994 -0.45923199999999997356" rpy="-1.6276681695418380185e-24 6.0643587944477814344e-25 1.3805821156841644938e-25" />
<geometry>
<mesh filename="package:///legjointconnector1.stl"/>
</geometry>
<material name="legjointconnector1_material">
<color rgba="0.2313725490196078538 0.38039215686274507888 0.7058823529411765163 1.0"/>
</material>
</visual>
<collision>
<origin xyz="0.038506400000000273742 -0.088899999999999756994 -0.45923199999999997356" rpy="-1.6276681695418380185e-24 6.0643587944477814344e-25 1.3805821156841644938e-25" />
<geometry>
<mesh filename="package:///legjointconnector1.stl"/>
</geometry>
</collision>
<inertial>
<origin xyz="-0.40919518440973640105 -0.029508437651028316534 -0.22545957775453845384" rpy="0 0 0"/>
<mass value="188.73631876709129074" />
<inertia ixx="4.6537577933983591549" ixy="-0.25943209440129066934"  ixz="0.036542406653603060063" iyy="5.7446693413348217661" iyz="0.16661863662344383874" izz="4.0892590965830573069" />
</inertial>
</link>

<link name="legjointconnector2">
<visual>
<origin xyz="0.070232476114742814488 -0.16024474380306930055 -0.43052999999999996827" rpy="1.570796326794896558 -9.8147944402058716702e-25 2.0439981505197109125e-24" />
<geometry>
<mesh filename="package:///legjointconnector2.stl"/>
</geometry>
<material name="legjointconnector2_material">
<color rgba="0.76862745098039220171 0.88627450980392152857 0.95294117647058818044 1.0"/>
</material>
</visual>
<collision>
<origin xyz="0.070232476114742814488 -0.16024474380306930055 -0.43052999999999996827" rpy="1.570796326794896558 -9.8147944402058716702e-25 2.0439981505197109125e-24" />
<geometry>
<mesh filename="package:///legjointconnector2.stl"/>
</geometry>
</collision>
<inertial>
<origin xyz="0.061843433631572665432 -0.16731335776010919369 -0.22965309411969195286" rpy="0 0 0"/>
<mass value="33.700879238921558567" />
<inertia ixx="1.8183343062068191287" ixy="0.17203321537692875531"  ixz="0.00026994432076556562801" iyy="1.7231385643804477681" iyz="-0.00019728284462270422798" izz="0.83789669946887190832" />
</inertial>
</link>

<link name="segment3">
<visual>
<origin xyz="-0.60765120142245421242 -0.063499999999999889866 -0.47548799999999991073" rpy="2.778105353313101558e-15 -2.9399340565868517662e-25 5.1851521988958171429e-26" />
<geometry>
<mesh filename="package:///legjointconnector3.stl"/>
</geometry>
<material name="legjointconnector3_material">
<color rgba="0.81176470588235294379 0.85882352941176465233 0.89803921568627453897 1.0"/>
</material>
</visual>
<collision>
<origin xyz="-0.60765120142245421242 -0.063499999999999889866 -0.47548799999999991073" rpy="2.778105353313101558e-15 -2.9399340565868517662e-25 5.1851521988958171429e-26" />
<geometry>
<mesh filename="package:///legjointconnector3.stl"/>
</geometry>
</collision>
<visual>
<origin xyz="-1.0160711528449073437 0.066674999999999928768 -0.11861799999999989019" rpy="-1.6670330741370230797e-15 5.1678151646605550362e-16 3.141592653589793116" />
<geometry>
<mesh filename="package:///motor.stl"/>
</geometry>
<material name="motor_material">
<color rgba="0.64705882352941179736 0.64705882352941179736 0.64705882352941179736 1.0"/>
</material>
</visual>
<collision>
<origin xyz="-1.0160711528449073437 0.066674999999999928768 -0.11861799999999989019" rpy="-1.6670330741370230797e-15 5.1678151646605550362e-16 3.141592653589793116" />
<geometry>
<mesh filename="package:///motor.stl"/>
</geometry>
</collision>
<visual>
<origin xyz="-0.14843125000000001457 -0.06667500000000003979 -0.11861800000000011224" rpy="3.7156385797227948791e-24 -2.9399454228018554182e-25 -3.2568709282231030058e-24" />
<geometry>
<mesh filename="package:///motor.stl"/>
</geometry>
<material name="motor_material">
<color rgba="0.64705882352941179736 0.64705882352941179736 0.64705882352941179736 1.0"/>
</material>
</visual>
<collision>
<origin xyz="-0.14843125000000001457 -0.06667500000000003979 -0.11861800000000011224" rpy="3.7156385797227948791e-24 -2.9399454228018554182e-25 -3.2568709282231030058e-24" />
<geometry>
<mesh filename="package:///motor.stl"/>
</geometry>
</collision>
<inertial>
<origin xyz="-0.58225120142245379018 0.029032930571645836765 -0.24178339289668318579" rpy="0 0 0"/>
<mass value="415.11154881410027429" />
<inertia ixx="7.8602906044070159908" ixy="9.1038288019262836315e-15"  ixz="2.7089441800853819586e-14" iyy="82.893177179425137524" iyz="0.12274391499229811431" izz="79.38228491783655727" />
</inertial>
</link>

<link name="legjointconnector4">
<visual>
<origin xyz="0.06695440000000019154 0.088899999999999979039 -0.3829050000000001619" rpy="3.141592653589793116 -2.4492936230744751806e-16 2.0094308408678293778e-24" />
<geometry>
<mesh filename="package:///legjointconnector4.stl"/>
</geometry>
<material name="legjointconnector4_material">
<color rgba="0.49803921568627451677 0.49803921568627451677 0.49803921568627451677 1.0"/>
</material>
</visual>
<collision>
<origin xyz="0.06695440000000019154 0.088899999999999979039 -0.3829050000000001619" rpy="3.141592653589793116 -2.4492936230744751806e-16 2.0094308408678293778e-24" />
<geometry>
<mesh filename="package:///legjointconnector4.stl"/>
</geometry>
</collision>
<inertial>
<origin xyz="-0.45997164835704518193 -0.0069451045546921469365 -0.22961600000000070843" rpy="0 0 0"/>
<mass value="114.5044662372232267" />
<inertia ixx="2.1154846818863148883" ixy="-0.35839006867214429075"  ixz="4.2154697545115421086e-14" iyy="9.3487420780648076146" iyz="-8.7780262321082508968e-17" izz="7.9984733077604808216" />
</inertial>
</link>

<joint name="BL_J4" type="revolute">
<origin xyz="-1.1645024028449062481 0 2.2204460492503130808e-16" rpy="1.6661838092530166565e-15 -5.2010781123730119761e-16 7.9619013065275774349e-18" />
<parent link="segment3" />
<child link="legjointconnector4" />
<axis xyz="0 0 1"/>
<limit effort="1" velocity="20" lower="0" upper="6.283185307179586232"/>
<joint_properties friction="0.0"/>
</joint>

<joint name="BL_J3" type="revolute">
<origin xyz="0.20990560000000013652 -0.25054560000000003495 0" rpy="-5.5681001479697635813e-16 3.0198503996277484511e-16 3.141592653589793116" />
<parent link="legjointconnector2" />
<child link="segment3" />
<axis xyz="0 0 1"/>
<limit effort="1" velocity="20" lower="0" upper="6.283185307179586232"/>
<joint_properties friction="0.0"/>
</joint>

<joint name="BL_J2" type="revolute">
<origin xyz="-0.45577759999999978291 -0.27635200000000015308 -0.12700000000000022382" rpy="-1.57079632679489678 3.8061645123399012522e-16 -3.141592653589793116" />
<parent link="segment1" />
<child link="legjointconnector2" />
<axis xyz="0 0 1"/>
<limit effort="1" velocity="20" lower="0" upper="6.283185307179586232"/>
<joint_properties friction="0.0"/>
</joint>

<joint name="BL_J1" type="revolute">
<origin xyz="0.49783999999999972719 0 0" rpy="1.2212454284373163526e-15 8.2675113504355278044e-16 1.5707963403039673089" />
<parent link="base" />
<child link="segment1" />
<axis xyz="0 0 1"/>
<limit effort="1" velocity="20" lower="0" upper="6.283185307179586232"/>
<joint_properties friction="0.0"/>
</joint>

<link name="segment1_2">
<visual>
<origin xyz="-0.38910259999999957659 -0.15773400000000004084 -0.2754312499999997943" rpy="1.570796326794896558 -1.570796326794896336 0" />
<geometry>
<mesh filename="package:///motor.stl"/>
</geometry>
<material name="motor_material">
<color rgba="0.64705882352941179736 0.64705882352941179736 0.64705882352941179736 1.0"/>
</material>
</visual>
<collision>
<origin xyz="-0.38910259999999957659 -0.15773400000000004084 -0.2754312499999997943" rpy="1.570796326794896558 -1.570796326794896336 0" />
<geometry>
<mesh filename="package:///motor.stl"/>
</geometry>
</collision>
<visual>
<origin xyz="0.038506400000000273742 -0.088899999999999979039 -0.45923199999999986254" rpy="-3.1319658658895335406e-24 1.3857085207255126295e-24 -3.2518657440344328097e-32" />
<geometry>
<mesh filename="package:///legjointconnector1.stl"/>
</geometry>
<material name="legjointconnector1_material">
<color rgba="0.2313725490196078538 0.38039215686274507888 0.7058823529411765163 1.0"/>
</material>
</visual>
<collision>
<origin xyz="0.038506400000000273742 -0.088899999999999979039 -0.45923199999999986254" rpy="-3.1319658658895335406e-24 1.3857085207255126295e-24 -3.2518657440344328097e-32" />
<geometry>
<mesh filename="package:///legjointconnector1.stl"/>
</geometry>
</collision>
<inertial>
<origin xyz="-0.40919518440973623452 -0.029508437651028320003 -0.22545957775453859262" rpy="0 0 0"/>
<mass value="188.73631876709129074" />
<inertia ixx="4.6537577933983564904" ixy="-0.25943209440128844889"  ixz="0.036542406653599278366" iyy="5.7446693413348253188" iyz="0.1666186366234438665" izz="4.0892590965830546423" />
</inertial>
</link>

<link name="legjointconnector2_2">
<visual>
<origin xyz="0.070232476114742814488 -0.16024474380306930055 -0.43053000000000002379" rpy="1.570796326794896558 -1.2780115521852562166e-31 -5.1850587869193827923e-26" />
<geometry>
<mesh filename="package:///legjointconnector2.stl"/>
</geometry>
<material name="legjointconnector2_material">
<color rgba="0.76862745098039220171 0.88627450980392152857 0.95294117647058818044 1.0"/>
</material>
</visual>
<collision>
<origin xyz="0.070232476114742814488 -0.16024474380306930055 -0.43053000000000002379" rpy="1.570796326794896558 -1.2780115521852562166e-31 -5.1850587869193827923e-26" />
<geometry>
<mesh filename="package:///legjointconnector2.stl"/>
</geometry>
</collision>
<inertial>
<origin xyz="0.061843433631572665432 -0.16731335776010919369 -0.22965309411969206388" rpy="0 0 0"/>
<mass value="33.700879238921558567" />
<inertia ixx="1.8183343062068191287" ixy="0.17203321537692878307"  ixz="0.0002699443207655655738" iyy="1.7231385643804482122" iyz="-0.00019728284462270420088" izz="0.83789669946887146423" />
</inertial>
</link>

<link name="segment3_2">
<visual>
<origin xyz="-0.60765120142245443446 -0.06350000000000011191 -0.47548800000000018828" rpy="1.4294121216809013674e-15 1.1259763146355128137e-16 -1.3684261562381220874e-24" />
<geometry>
<mesh filename="package:///legjointconnector3.stl"/>
</geometry>
<material name="legjointconnector3_material">
<color rgba="0.81176470588235294379 0.85882352941176465233 0.89803921568627453897 1.0"/>
</material>
</visual>
<collision>
<origin xyz="-0.60765120142245443446 -0.06350000000000011191 -0.47548800000000018828" rpy="1.4294121216809013674e-15 1.1259763146355128137e-16 -1.3684261562381220874e-24" />
<geometry>
<mesh filename="package:///legjointconnector3.stl"/>
</geometry>
</collision>
<visual>
<origin xyz="-1.016071152844908454 0.066674999999999817746 -0.11861799999999972366" rpy="-1.4294121150634566642e-15 -1.1259763146355135533e-16 3.141592653589793116" />
<geometry>
<mesh filename="package:///motor.stl"/>
</geometry>
<material name="motor_material">
<color rgba="0.64705882352941179736 0.64705882352941179736 0.64705882352941179736 1.0"/>
</material>
</visual>
<collision>
<origin xyz="-1.016071152844908454 0.066674999999999817746 -0.11861799999999972366" rpy="-1.4294121150634566642e-15 -1.1259763146355135533e-16 3.141592653589793116" />
<geometry>
<mesh filename="package:///motor.stl"/>
</geometry>
</collision>
<visual>
<origin xyz="-0.14843125000000001457 -0.06667500000000003979 -0.1186179999999999457" rpy="-1.335826228064705228e-24 1.8150320491720380046e-31 -1.3684261562381360464e-24" />
<geometry>
<mesh filename="package:///motor.stl"/>
</geometry>
<material name="motor_material">
<color rgba="0.64705882352941179736 0.64705882352941179736 0.64705882352941179736 1.0"/>
</material>
</visual>
<collision>
<origin xyz="-0.14843125000000001457 -0.06667500000000003979 -0.1186179999999999457" rpy="-1.335826228064705228e-24 1.8150320491720380046e-31 -1.3684261562381360464e-24" />
<geometry>
<mesh filename="package:///motor.stl"/>
</geometry>
</collision>
<inertial>
<origin xyz="-0.58225120142245434529 0.029032930571645777784 -0.24178339289668318579" rpy="0 0 0"/>
<mass value="415.11154881410027429" />
<inertia ixx="7.8602906044070213198" ixy="-4.4408920985006261617e-16"  ixz="7.4384942649885488208e-15" iyy="82.893177179425308054" iyz="0.12274391499228466673" izz="79.3822849178367278" />
</inertial>
</link>

<link name="legjointconnector4_2">
<visual>
<origin xyz="0.06695440000000019154 0.088900000000000090061 -0.38290499999999999536" rpy="-3.141592653589793116 -2.4492935982947054283e-16 0" />
<geometry>
<mesh filename="package:///legjointconnector4.stl"/>
</geometry>
<material name="legjointconnector4_material">
<color rgba="0.49803921568627451677 0.49803921568627451677 0.49803921568627451677 1.0"/>
</material>
</visual>
<collision>
<origin xyz="0.06695440000000019154 0.088900000000000090061 -0.38290499999999999536" rpy="-3.141592653589793116 -2.4492935982947054283e-16 0" />
<geometry>
<mesh filename="package:///legjointconnector4.stl"/>
</geometry>
</collision>
<inertial>
<origin xyz="-0.45997164835704507091 -0.0069451045546920081586 -0.2296160000000005974" rpy="0 0 0"/>
<mass value="114.5044662372232267" />
<inertia ixx="2.1154846818863140001" ixy="-0.35839006867214417973"  ixz="4.2154697562485513441e-14" iyy="9.3487420780648040619" iyz="-8.7780220809197077051e-17" izz="7.9984733077604754925" />
</inertial>
</link>

<joint name="FR_J4" type="revolute">
<origin xyz="-1.1645024028449086906 -1.1102230246251565404e-16 1.6653345369377348106e-16" rpy="1.605866653096347499e-15 -4.3247425860249348976e-18 -4.0123531872111090802e-17" />
<parent link="segment3_2" />
<child link="legjointconnector4_2" />
<axis xyz="0 0 1"/>
<limit effort="1" velocity="20" lower="0" upper="6.283185307179586232"/>
<joint_properties friction="0.0"/>
</joint>

<joint name="FR_J3" type="revolute">
<origin xyz="0.2099056000000000255 -0.25054559999999992392 -5.5511151231257827021e-17" rpy="5.5511156512876473097e-17 1.8316849040800762374e-31 3.141592653589793116" />
<parent link="legjointconnector2_2" />
<child link="segment3_2" />
<axis xyz="0 0 1"/>
<limit effort="1" velocity="20" lower="0" upper="6.283185307179586232"/>
<joint_properties friction="0.0"/>
</joint>

<joint name="FR_J2" type="revolute">
<origin xyz="-0.4557775999999997274 -0.27635199999999998655 -0.12699999999999977973" rpy="-1.5707963267948947816 5.8286706669016316343e-16 3.141592653589793116" />
<parent link="segment1_2" />
<child link="legjointconnector2_2" />
<axis xyz="0 0 1"/>
<limit effort="1" velocity="20" lower="0" upper="6.283185307179586232"/>
<joint_properties friction="0.0"/>
</joint>

<joint name="FR_J1" type="revolute">
<origin xyz="0 0.96519999999999961382 0" rpy="2.9004576563626872302e-15 1.013078515305890832e-15 -1.5707963267948972241" />
<parent link="base" />
<child link="segment1_2" />
<axis xyz="0 0 1"/>
<limit effort="1" velocity="20" lower="0" upper="6.283185307179586232"/>
<joint_properties friction="0.0"/>
</joint>

<link name="segment1inverse_2">
<visual>
<origin xyz="-0.52245259999999993372 0.15773400000000026289 -0.27543125000000001634" rpy="-1.570796326794896558 -1.5707963267948961139 0" />
<geometry>
<mesh filename="package:///motor.stl"/>
</geometry>
<material name="motor_material">
<color rgba="0.64705882352941179736 0.64705882352941179736 0.64705882352941179736 1.0"/>
</material>
</visual>
<collision>
<origin xyz="-0.52245259999999993372 0.15773400000000026289 -0.27543125000000001634" rpy="-1.570796326794896558 -1.5707963267948961139 0" />
<geometry>
<mesh filename="package:///motor.stl"/>
</geometry>
</collision>
<visual>
<origin xyz="0.038506400000000218231 -0.088899999999999756994 -0.45923199999999986254" rpy="2.6716521171657696312e-24 3.4567536210088759983e-26 2.0118181531195613038e-32" />
<geometry>
<mesh filename="package:///legjointconnector1.stl"/>
</geometry>
<material name="legjointconnector1_material">
<color rgba="0.2313725490196078538 0.38039215686274507888 0.7058823529411765163 1.0"/>
</material>
</visual>
<collision>
<origin xyz="0.038506400000000218231 -0.088899999999999756994 -0.45923199999999986254" rpy="2.6716521171657696312e-24 3.4567536210088759983e-26 2.0118181531195613038e-32" />
<geometry>
<mesh filename="package:///legjointconnector1.stl"/>
</geometry>
</collision>
<inertial>
<origin xyz="-0.40919518440973651208 0.029508437651028632254 -0.22545957775453856486" rpy="0 0 0"/>
<mass value="188.73631876709129074" />
<inertia ixx="4.6537577933983609313" ixy="0.25943209440128911503"  ixz="0.036542406653598535904" iyy="5.7446693413348270951" iyz="-0.16661863662344689185" izz="4.0892590965830617478" />
</inertial>
</link>

<link name="legjointconnector2_3">
<visual>
<origin xyz="0.07023247611474292551 0.16024474380306918952 -0.028701999999999783242" rpy="-1.570796326794896558 -2.0116180994100064909e-31 -1.2647239589865029489e-24" />
<geometry>
<mesh filename="package:///legjointconnector2.stl"/>
</geometry>
<material name="legjointconnector2_material">
<color rgba="0.76862745098039220171 0.88627450980392152857 0.95294117647058818044 1.0"/>
</material>
</visual>
<collision>
<origin xyz="0.07023247611474292551 0.16024474380306918952 -0.028701999999999783242" rpy="-1.570796326794896558 -2.0116180994100064909e-31 -1.2647239589865029489e-24" />
<geometry>
<mesh filename="package:///legjointconnector2.stl"/>
</geometry>
</collision>
<inertial>
<origin xyz="0.061843433631572783393 0.16731335776010908267 -0.22957890588030771539" rpy="0 0 0"/>
<mass value="33.700879238921558567" />
<inertia ixx="1.8183343062068191287" ixy="-0.17203321537692878307"  ixz="-0.00026994432076556551959" iyy="1.7231385643804482122" iyz="-0.00019728284462270417377" izz="0.83789669946887124219" />
</inertial>
</link>

<link name="segment3_3">
<visual>
<origin xyz="-0.55685120142245425612 0.063500000000000000888 -0.47548800000000024379" rpy="1.1102228104420051106e-16 1.1259769121638389263e-16 3.141592653589793116" />
<geometry>
<mesh filename="package:///legjointconnector3.stl"/>
</geometry>
<material name="legjointconnector3_material">
<color rgba="0.81176470588235294379 0.85882352941176465233 0.89803921568627453897 1.0"/>
</material>
</visual>
<collision>
<origin xyz="-0.55685120142245425612 0.063500000000000000888 -0.47548800000000024379" rpy="1.1102228104420051106e-16 1.1259769121638389263e-16 3.141592653589793116" />
<geometry>
<mesh filename="package:///legjointconnector3.stl"/>
</geometry>
</collision>
<visual>
<origin xyz="-0.14843125000000023661 -0.06667500000000003979 -0.11861800000000011224" rpy="-4.2376321053686627128e-24 2.0116180994100064909e-31 -1.2647239589865029489e-24" />
<geometry>
<mesh filename="package:///motor.stl"/>
</geometry>
<material name="motor_material">
<color rgba="0.64705882352941179736 0.64705882352941179736 0.64705882352941179736 1.0"/>
</material>
</visual>
<collision>
<origin xyz="-0.14843125000000023661 -0.06667500000000003979 -0.11861800000000011224" rpy="-4.2376321053686627128e-24 2.0116180994100064909e-31 -1.2647239589865029489e-24" />
<geometry>
<mesh filename="package:///motor.stl"/>
</geometry>
</collision>
<visual>
<origin xyz="-1.0160711528449082319 0.06667500000000003979 -0.11861800000000033428" rpy="1.1102229427909032424e-16 1.1259769121638394193e-16 3.141592653589793116" />
<geometry>
<mesh filename="package:///motor.stl"/>
</geometry>
<material name="motor_material">
<color rgba="0.64705882352941179736 0.64705882352941179736 0.64705882352941179736 1.0"/>
</material>
</visual>
<collision>
<origin xyz="-1.0160711528449082319 0.06667500000000003979 -0.11861800000000033428" rpy="1.1102229427909032424e-16 1.1259769121638394193e-16 3.141592653589793116" />
<geometry>
<mesh filename="package:///motor.stl"/>
</geometry>
</collision>
<inertial>
<origin xyz="-0.58225120142245423427 -0.029032930571645836765 -0.24178339289668351886" rpy="0 0 0"/>
<mass value="415.11154881410027429" />
<inertia ixx="7.8602906044070177671" ixy="1.1324274851176596712e-14"  ixz="-1.1490808304870370193e-14" iyy="82.893177179425237" iyz="-0.12274391499226783298" izz="79.382284917836642535" />
</inertial>
</link>

<link name="legjointconnector4_3">
<visual>
<origin xyz="0.06695439999999974745 -0.088899999999999979039 -0.076326999999999811664" rpy="5.2816190246481502684e-24 3.9981520600939181951e-32 1.3684269748777048423e-24" />
<geometry>
<mesh filename="package:///legjointconnector4.stl"/>
</geometry>
<material name="legjointconnector4_material">
<color rgba="0.49803921568627451677 0.49803921568627451677 0.49803921568627451677 1.0"/>
</material>
</visual>
<collision>
<origin xyz="0.06695439999999974745 -0.088899999999999979039 -0.076326999999999811664" rpy="5.2816190246481502684e-24 3.9981520600939181951e-32 1.3684269748777048423e-24" />
<geometry>
<mesh filename="package:///legjointconnector4.stl"/>
</geometry>
</collision>
<inertial>
<origin xyz="-0.459971648357045515 0.0069451045546921191809 -0.2296159999999993484" rpy="0 0 0"/>
<mass value="114.5044662372232267" />
<inertia ixx="2.1154846818863140001" ixy="0.35839006867214417973"  ixz="-4.3595614199734512857e-14" iyy="9.3487420780648040619" iyz="8.5111965419340093998e-23" izz="7.9984733077604754925" />
</inertial>
</link>

<joint name="BR_J4" type="revolute">
<origin xyz="-1.1645024028449080244 0 -4.4408920985006261617e-16" rpy="-9.0442043540577272659e-17 -4.478155192180798781e-17 -2.5970077749655048884e-17" />
<parent link="segment3_3" />
<child link="legjointconnector4_3" />
<axis xyz="0 0 1"/>
<limit effort="1" velocity="20" lower="0" upper="6.283185307179586232"/>
<joint_properties friction="0.0"/>
</joint>

<joint name="BR_J3" type="revolute">
<origin xyz="0.20990560000000035856 0.25054559999999992392 0" rpy="-4.2376321053686627128e-24 2.0116180994100064909e-31 3.141592653589793116" />
<parent link="legjointconnector2_3" />
<child link="segment3_3" />
<axis xyz="0 0 1"/>
<limit effort="1" velocity="20" lower="0" upper="6.283185307179586232"/>
<joint_properties friction="0.0"/>
</joint>

<joint name="BR_J2" type="revolute">
<origin xyz="-0.45577759999999967189 0.27635200000000015308 -0.12700000000000000178" rpy="1.570796326794896336 1.1102231566283779189e-16 -3.141592653589793116" />
<parent link="segment1inverse_2" />
<child link="legjointconnector2_3" />
<axis xyz="0 0 1"/>
<limit effort="1" velocity="20" lower="0" upper="6.283185307179586232"/>
<joint_properties friction="0.0"/>
</joint>

<joint name="BR_J1" type="revolute">
<origin xyz="0.49783999999999972719 0.9651999999999995028 0" rpy="1.7764361321532213574e-23 1.1952881864215707969e-23 -1.57079632679489678" />
<parent link="base" />
<child link="segment1inverse_2" />
<axis xyz="0 0 1"/>
<limit effort="1" velocity="20" lower="0" upper="6.283185307179586232"/>
<joint_properties friction="0.0"/>
</joint>

<joint name="FL_J1" type="revolute">
<origin xyz="-0.57807399120160729566 -0.5988052311389459037 -0.77874950167232726006" rpy="-2.3872993578795250843e-08 3.8169197161100659601e-08 -1.5707963267948970021" />
<parent link="segment1inverse" />
<child link="base" />
<axis xyz="0 0 1"/>
<limit effort="1" velocity="20" lower="0" upper="6.283185307179586232"/>
<joint_properties friction="0.0"/>
</joint>

<link name="legjointconnector2_4">
<visual>
<origin xyz="0.070232476114743036533 0.16024474380306918952 -0.028701999999999949775" rpy="-1.570796326794896558 -1.4761462486967363545e-32 1.2647243780687963994e-24" />
<geometry>
<mesh filename="package:///legjointconnector2.stl"/>
</geometry>
<material name="legjointconnector2_material">
<color rgba="0.76862745098039220171 0.88627450980392152857 0.95294117647058818044 1.0"/>
</material>
</visual>
<collision>
<origin xyz="0.070232476114743036533 0.16024474380306918952 -0.028701999999999949775" rpy="-1.570796326794896558 -1.4761462486967363545e-32 1.2647243780687963994e-24" />
<geometry>
<mesh filename="package:///legjointconnector2.stl"/>
</geometry>
</collision>
<inertial>
<origin xyz="0.061843433631572887477 0.16731335776010908267 -0.22957890588030788193" rpy="0 0 0"/>
<mass value="33.700879238921558567" />
<inertia ixx="1.8183343062068191287" ixy="-0.17203321537692878307"  ixz="-0.00026994432076556551959" iyy="1.7231385643804482122" iyz="-0.00019728284462270417377" izz="0.83789669946887124219" />
</inertial>
</link>

<link name="segment3_4">
<visual>
<origin xyz="-0.55685120142245358998 0.06350000000000011191 -0.4754879999999993001" rpy="1.110223106459403429e-16 -5.5511151231257179909e-17 -3.141592653589793116" />
<geometry>
<mesh filename="package:///legjointconnector3.stl"/>
</geometry>
<material name="legjointconnector3_material">
<color rgba="0.81176470588235294379 0.85882352941176465233 0.89803921568627453897 1.0"/>
</material>
</visual>
<collision>
<origin xyz="-0.55685120142245358998 0.06350000000000011191 -0.4754879999999993001" rpy="1.110223106459403429e-16 -5.5511151231257179909e-17 -3.141592653589793116" />
<geometry>
<mesh filename="package:///legjointconnector3.stl"/>
</geometry>
</collision>
<visual>
<origin xyz="-0.14843125000000001457 -0.066674999999999928768 -0.1186179999999999457" rpy="4.2376321985735561575e-24 -1.692547545184039146e-32 -2.0439980721433205449e-24" />
<geometry>
<mesh filename="package:///motor.stl"/>
</geometry>
<material name="motor_material">
<color rgba="0.64705882352941179736 0.64705882352941179736 0.64705882352941179736 1.0"/>
</material>
</visual>
<collision>
<origin xyz="-0.14843125000000001457 -0.066674999999999928768 -0.1186179999999999457" rpy="4.2376321985735561575e-24 -1.692547545184039146e-32 -2.0439980721433205449e-24" />
<geometry>
<mesh filename="package:///motor.stl"/>
</geometry>
</collision>
<visual>
<origin xyz="-1.0160711528449071217 0.06667500000000003979 -0.11861799999999972366" rpy="1.1102228841379292739e-16 1.1778011199458197558e-30 3.141592653589793116" />
<geometry>
<mesh filename="package:///motor.stl"/>
</geometry>
<material name="motor_material">
<color rgba="0.64705882352941179736 0.64705882352941179736 0.64705882352941179736 1.0"/>
</material>
</visual>
<collision>
<origin xyz="-1.0160711528449071217 0.06667500000000003979 -0.11861799999999972366" rpy="1.1102228841379292739e-16 1.1778011199458197558e-30 3.141592653589793116" />
<geometry>
<mesh filename="package:///motor.stl"/>
</geometry>
</collision>
<inertial>
<origin xyz="-0.58225120142245356814 -0.029032930571645760437 -0.2417833928966829915" rpy="0 0 0"/>
<mass value="415.11154881410027429" />
<inertia ixx="7.8602906044070035563" ixy="3.5527136788005009294e-15"  ixz="2.6589841439772499143e-14" iyy="82.893177179425123313" iyz="-0.12274391499226641744" izz="79.382284917836500426" />
</inertial>
</link>

<link name="legjointconnector4_4">
<visual>
<origin xyz="0.066954400000000635629 -0.088899999999999979039 -0.076326999999999811664" rpy="1.3234889800848445737e-23 -6.4823123838383570114e-32 -7.2742257464848162839e-25" />
<geometry>
<mesh filename="package:///legjointconnector4.stl"/>
</geometry>
<material name="legjointconnector4_material">
<color rgba="0.49803921568627451677 0.49803921568627451677 0.49803921568627451677 1.0"/>
</material>
</visual>
<collision>
<origin xyz="0.066954400000000635629 -0.088899999999999979039 -0.076326999999999811664" rpy="1.3234889800848445737e-23 -6.4823123838383570114e-32 -7.2742257464848162839e-25" />
<geometry>
<mesh filename="package:///legjointconnector4.stl"/>
</geometry>
</collision>
<inertial>
<origin xyz="-0.45997164835704462682 0.0069451045546921053031 -0.2296159999999993484" rpy="0 0 0"/>
<mass value="114.5044662372232267" />
<inertia ixx="2.1154846818863140001" ixy="0.35839006867214412422"  ixz="-4.3595614196884143836e-14" iyy="9.3487420780648005092" iyz="7.9643808648286585732e-23" izz="7.9984733077604754925" />
</inertial>
</link>

<joint name="FL_J4" type="revolute">
<origin xyz="-1.1645024028449064701 -1.1102230246251565404e-16 1.1102230246251565404e-16" rpy="-1.110222826101810144e-16 -1.1778011199458197558e-30 -1.5278887872991683262e-23" />
<parent link="segment3_4" />
<child link="legjointconnector4_4" />
<axis xyz="0 0 1"/>
<limit effort="1" velocity="20" lower="0" upper="6.3006385996995293297"/>
<joint_properties friction="0.0"/>
</joint>

<joint name="FL_J3" type="revolute">
<origin xyz="0.20990560000000035856 0.2505455999999998129 5.5511151231257827021e-17" rpy="4.2376321985735554229e-24 1.0729593300831567566e-17 3.141592653589793116" />
<parent link="legjointconnector2_4" />
<child link="segment3_4" />
<axis xyz="0 0 1"/>
<limit effort="1" velocity="20" lower="0" upper="6.283185307179586232"/>
<joint_properties friction="0.0"/>
</joint>

<joint name="FL_J2" type="revolute">
<origin xyz="-1.0338515942334769449 -0.32245322629145822813 -0.90574948024341750408" rpy="1.5707962886256991997 -2.3872993467772918602e-08 -3.1415926535897926719" />
<parent link="segment1inverse" />
<child link="legjointconnector2_4" />
<axis xyz="0 0 1"/>
<limit effort="1" velocity="20" lower="0" upper="6.283185307179586232"/>
<joint_properties friction="0.0"/>
</joint>


</robot>
