<robot name="onshape">
<link name="base">
<visual>
<origin xyz="-0.68018618325141355641 -0.77836459757771037093 -0.2599892372525848816" rpy="1.5386514007653082967e-08 4.136606557689327442e-08 -0.69813169526437079959" />
<geometry>
<mesh filename="package:///motor.stl"/>
</geometry>
<material name="motor_material">
<color rgba="0.64705882352941179736 0.64705882352941179736 0.64705882352941179736 1.0"/>
</material>
</visual>
<collision>
<origin xyz="-0.68018618325141355641 -0.77836459757771037093 -0.2599892372525848816" rpy="1.5386514007653082967e-08 4.136606557689327442e-08 -0.69813169526437079959" />
<geometry>
<mesh filename="package:///motor.stl"/>
</geometry>
</collision>
<visual>
<origin xyz="-1.0597486169757592833 -0.28579784178566564057 -0.25998921007597636246" rpy="-1.5386514165201171452e-08 -4.1366064709380387372e-08 2.4434609583254234266" />
<geometry>
<mesh filename="package:///motor.stl"/>
</geometry>
<material name="motor_material">
<color rgba="0.64705882352941179736 0.64705882352941179736 0.64705882352941179736 1.0"/>
</material>
</visual>
<collision>
<origin xyz="-1.0597486169757592833 -0.28579784178566564057 -0.25998921007597636246" rpy="-1.5386514165201171452e-08 -4.1366064709380387372e-08 2.4434609583254234266" />
<geometry>
<mesh filename="package:///motor.stl"/>
</geometry>
</collision>
<visual>
<origin xyz="-0.059767586473256535673 -0.038978497646272099175 -0.25998922240152178009" rpy="1.5386513844399099308e-08 4.1366065512371697716e-08 -0.69813169526437102164" />
<geometry>
<mesh filename="package:///motor.stl"/>
</geometry>
<material name="motor_material">
<color rgba="0.64705882352941179736 0.64705882352941179736 0.64705882352941179736 1.0"/>
</material>
</visual>
<collision>
<origin xyz="-0.059767586473256535673 -0.038978497646272099175 -0.25998922240152178009" rpy="1.5386513844399099308e-08 4.1366065512371697716e-08 -0.69813169526437102164" />
<geometry>
<mesh filename="package:///motor.stl"/>
</geometry>
</collision>
<visual>
<origin xyz="-0.77661850693285938707 -0.33686214394097313551 -0.28437321820730343536" rpy="-1.5707963114083824951 4.136606507362698783e-08 -0.69813169526436991141" />
<geometry>
<mesh filename="package:///baseplate.stl"/>
</geometry>
<material name="baseplate_material">
<color rgba="0.43921568627450979783 0.47450980392156860699 0.50196078431372548323 1.0"/>
</material>
</visual>
<collision>
<origin xyz="-0.77661850693285938707 -0.33686214394097313551 -0.28437321820730343536" rpy="-1.5707963114083824951 4.136606507362698783e-08 -0.69813169526436991141" />
<geometry>
<mesh filename="package:///baseplate.stl"/>
</geometry>
</collision>
<visual>
<origin xyz="-0.43933002019760314383 0.4535882581457729712 -0.25998919522491303891" rpy="-1.5386514229975246692e-08 -4.1366064456472866465e-08 2.4434609583254229825" />
<geometry>
<mesh filename="package:///motor.stl"/>
</geometry>
<material name="motor_material">
<color rgba="0.64705882352941179736 0.64705882352941179736 0.64705882352941179736 1.0"/>
</material>
</visual>
<collision>
<origin xyz="-0.43933002019760314383 0.4535882581457729712 -0.25998919522491303891" rpy="-1.5386514229975246692e-08 -4.1366064456472866465e-08 2.4434609583254229825" />
<geometry>
<mesh filename="package:///motor.stl"/>
</geometry>
</collision>
<inertial>
<origin xyz="-0.55889969120758575816 -0.16281071528719959218 -0.43853106493353521955" rpy="0 0 0"/>
<mass value="1406.2088699182118035" />
<inertia ixx="229.76847627583339317" ixy="25.688424731455111072"  ixz="0.86795743367189492901" iyy="238.76229640209706417" iyz="-0.75828716275291174753" izz="410.74917094328253597" />
</inertial>
</link>

<link name="segment1">
<visual>
<origin xyz="-0.38910259999999996516 -0.15773399999999973553 -0.27543124999999840652" rpy="1.5707963267948947816 -1.570796326794896336 0" />
<geometry>
<mesh filename="package:///motor.stl"/>
</geometry>
<material name="motor_material">
<color rgba="0.64705882352941179736 0.64705882352941179736 0.64705882352941179736 1.0"/>
</material>
</visual>
<collision>
<origin xyz="-0.38910259999999996516 -0.15773399999999973553 -0.27543124999999840652" rpy="1.5707963267948947816 -1.570796326794896336 0" />
<geometry>
<mesh filename="package:///motor.stl"/>
</geometry>
</collision>
<visual>
<origin xyz="0.038506400000000384765 -0.088899999999999951283 -0.45923199999999991805" rpy="-2.3594425463589673839e-24 -2.6299558701564584806e-24 -1.7276370907223099977e-17" />
<geometry>
<mesh filename="package:///legjointconnector1.stl"/>
</geometry>
<material name="legjointconnector1_material">
<color rgba="0.2313725490196078538 0.38039215686274507888 0.7058823529411765163 1.0"/>
</material>
</visual>
<collision>
<origin xyz="0.038506400000000384765 -0.088899999999999951283 -0.45923199999999991805" rpy="-2.3594425463589673839e-24 -2.6299558701564584806e-24 -1.7276370907223099977e-17" />
<geometry>
<mesh filename="package:///legjointconnector1.stl"/>
</geometry>
</collision>
<inertial>
<origin xyz="-0.40919518440973634554 -0.029508437651028691234 -0.22545957775453762117" rpy="0 0 0"/>
<mass value="188.73631876709129074" />
<inertia ixx="4.6537577933983360623" ixy="-0.25943209440129799681"  ixz="0.036542406653606203382" iyy="5.7446693413347986734" iyz="0.16661863662344594816" izz="4.0892590965830395433" />
</inertial>
</link>

<link name="legjointconnector2">
<visual>
<origin xyz="0.070232476114742814488 -0.16024474380306930055 -0.43052999999999974623" rpy="1.570796326794896558 2.9353182442914868302e-17 4.1548089648494116087e-24" />
<geometry>
<mesh filename="package:///legjointconnector2.stl"/>
</geometry>
<material name="legjointconnector2_material">
<color rgba="0.76862745098039220171 0.88627450980392152857 0.95294117647058818044 1.0"/>
</material>
</visual>
<collision>
<origin xyz="0.070232476114742814488 -0.16024474380306930055 -0.43052999999999974623" rpy="1.570796326794896558 2.9353182442914868302e-17 4.1548089648494116087e-24" />
<geometry>
<mesh filename="package:///legjointconnector2.stl"/>
</geometry>
</collision>
<inertial>
<origin xyz="0.061843433631572686249 -0.16731335776010919369 -0.22965309411969181408" rpy="0 0 0"/>
<mass value="33.700879238921572778" />
<inertia ixx="1.8183343062068202389" ixy="0.17203321537692881082"  ixz="0.00026994432076552209729" iyy="1.7231385643804484342" iyz="-0.00019728284462275748942" izz="0.83789669946887124219" />
</inertial>
</link>

<link name="segment3">
<visual>
<origin xyz="-0.60765120142245421242 -0.06349999999999998701 -0.47548799999999963317" rpy="4.062179194684770147e-18 2.2493300914570839666e-16 -5.448044507986625325e-24" />
<geometry>
<mesh filename="package:///legjointconnector3.stl"/>
</geometry>
<material name="legjointconnector3_material">
<color rgba="0.81176470588235294379 0.85882352941176465233 0.89803921568627453897 1.0"/>
</material>
</visual>
<collision>
<origin xyz="-0.60765120142245421242 -0.06349999999999998701 -0.47548799999999963317" rpy="4.062179194684770147e-18 2.2493300914570839666e-16 -5.448044507986625325e-24" />
<geometry>
<mesh filename="package:///legjointconnector3.stl"/>
</geometry>
</collision>
<visual>
<origin xyz="-1.0160711528449091201 0.066675000000000012035 -0.11861799999999933508" rpy="-2.0697470070173434827e-17 -2.6694338012102400195e-17 3.141592653589793116" />
<geometry>
<mesh filename="package:///motor.stl"/>
</geometry>
<material name="motor_material">
<color rgba="0.64705882352941179736 0.64705882352941179736 0.64705882352941179736 1.0"/>
</material>
</visual>
<collision>
<origin xyz="-1.0160711528449091201 0.066675000000000012035 -0.11861799999999933508" rpy="-2.0697470070173434827e-17 -2.6694338012102400195e-17 3.141592653589793116" />
<geometry>
<mesh filename="package:///motor.stl"/>
</geometry>
</collision>
<visual>
<origin xyz="-0.14843124999999979252 -0.066675000000000025913 -0.11861799999999983468" rpy="-2.9642229231751351487e-24 2.6694338012102538862e-17 1.1694003924376025025e-24" />
<geometry>
<mesh filename="package:///motor.stl"/>
</geometry>
<material name="motor_material">
<color rgba="0.64705882352941179736 0.64705882352941179736 0.64705882352941179736 1.0"/>
</material>
</visual>
<collision>
<origin xyz="-0.14843124999999979252 -0.066675000000000025913 -0.11861799999999983468" rpy="-2.9642229231751351487e-24 2.6694338012102538862e-17 1.1694003924376025025e-24" />
<geometry>
<mesh filename="package:///motor.stl"/>
</geometry>
</collision>
<inertial>
<origin xyz="-0.58225120142245434529 0.02903293057164592697 -0.24178339289668285272" rpy="0 0 0"/>
<mass value="415.11154881410027429" />
<inertia ixx="7.8602906044070230962" ixy="-1.7763568394002504647e-15"  ixz="3.6359804056473876699e-14" iyy="82.893177179425421741" iyz="0.12274391499226638969" izz="79.382284917836813065" />
</inertial>
</link>

<link name="legjointconnector4">
<visual>
<origin xyz="0.066954399999999303361 0.088900000000000006795 -0.38290499999999977332" rpy="3.141592653589793116 -2.4503037092180949948e-16 -3.1092563695511802293e-24" />
<geometry>
<mesh filename="package:///legjointconnector4.stl"/>
</geometry>
<material name="legjointconnector4_material">
<color rgba="0.49803921568627451677 0.49803921568627451677 0.49803921568627451677 1.0"/>
</material>
</visual>
<collision>
<origin xyz="0.066954399999999303361 0.088900000000000006795 -0.38290499999999977332" rpy="3.141592653589793116 -2.4503037092180949948e-16 -3.1092563695511802293e-24" />
<geometry>
<mesh filename="package:///legjointconnector4.stl"/>
</geometry>
</collision>
<inertial>
<origin xyz="-0.45470653616358835958 -0.0064117836026283958617 -0.22961601618582505591" rpy="0 0 0"/>
<mass value="113.67855069945751723" />
<inertia ixx="2.1103224452338626982" ixy="-0.31372494572636577814"  ixz="-9.9897013585807493937e-07" iyy="8.909145154302921199" iyz="1.3223695419124541502e-07" izz="7.5543498430532345367" />
</inertial>
</link>

<joint name="BL_J4" type="revolute">
<origin xyz="-1.1645024028449084685 -3.1086244689504383132e-15 1.7208456881689926377e-15" rpy="-1.4753334857957956014e-15 1.7721323323395540624e-16 4.218851918506896105e-15" />
<parent link="segment3" />
<child link="legjointconnector4" />
<axis xyz="0 0 1"/>
<limit effort="1" velocity="20" lower="-0.34906585039886589561" upper="1.0471975511965976313"/>
<joint_properties friction="0.0"/>
</joint>

<joint name="BL_J3" type="revolute">
<origin xyz="0.20990560000000035856 -0.25054559999999992392 -5.5511151231257827021e-17" rpy="4.0009830263683715674e-15 3.7623924145558519288e-15 3.1415926535897891192" />
<parent link="legjointconnector2" />
<child link="segment3" />
<axis xyz="0 0 1"/>
<limit effort="1" velocity="20" lower="-0.1745329251994329478" upper="0.1745329251994329478"/>
<joint_properties friction="0.0"/>
</joint>

<joint name="BL_J2" type="revolute">
<origin xyz="-0.45577759999999956086 -0.27635199999999870979 -0.12699999999999922462" rpy="-1.570796326794896336 -5.5823697141391807618e-17 -3.1415926535897860106" />
<parent link="segment1" />
<child link="legjointconnector2" />
<axis xyz="0 0 1"/>
<limit effort="1" velocity="20" lower="-0.52359877559829881566" upper="1.3962634015954635824"/>
<joint_properties friction="0.0"/>
</joint>

<joint name="BL_J1" type="revolute">
<origin xyz="-0.52362338229691240965 -0.82269835640884436678 -0.14137124236670622901" rpy="4.1366065576892837669e-08 -1.5386514007654697624e-08 0.87266463153052697965" />
<parent link="base" />
<child link="segment1" />
<axis xyz="0 0 1"/>
<limit effort="1" velocity="20" lower="0" upper="0.87266462599716476678"/>
<joint_properties friction="0.0"/>
</joint>

<link name="segment1inverse">
<visual>
<origin xyz="-0.52245259999999960066 0.1577339999999998188 -0.27543124999999801794" rpy="-1.5707963267948934494 -1.5707963267948961139 0" />
<geometry>
<mesh filename="package:///motor.stl"/>
</geometry>
<material name="motor_material">
<color rgba="0.64705882352941179736 0.64705882352941179736 0.64705882352941179736 1.0"/>
</material>
</visual>
<collision>
<origin xyz="-0.52245259999999960066 0.1577339999999998188 -0.27543124999999801794" rpy="-1.5707963267948934494 -1.5707963267948961139 0" />
<geometry>
<mesh filename="package:///motor.stl"/>
</geometry>
</collision>
<visual>
<origin xyz="0.03850640000000016272 -0.088899999999999979039 -0.45923199999999986254" rpy="1.0013444732289341124e-24 1.6486979533615037228e-24 -4.9928761440132623273e-17" />
<geometry>
<mesh filename="package:///legjointconnector1.stl"/>
</geometry>
<material name="legjointconnector1_material">
<color rgba="0.2313725490196078538 0.38039215686274507888 0.7058823529411765163 1.0"/>
</material>
</visual>
<collision>
<origin xyz="0.03850640000000016272 -0.088899999999999979039 -0.45923199999999986254" rpy="1.0013444732289341124e-24 1.6486979533615037228e-24 -4.9928761440132623273e-17" />
<geometry>
<mesh filename="package:///legjointconnector1.stl"/>
</geometry>
</collision>
<inertial>
<origin xyz="-0.40919518440973745577 0.029508437651029319204 -0.22545957775453739913" rpy="0 0 0"/>
<mass value="188.73631876709129074" />
<inertia ixx="4.6537577933982339218" ixy="0.25943209440130826637"  ixz="0.036542406653607667488" iyy="5.7446693413348004498" iyz="-0.16661863662344589265" izz="4.089259096583052866" />
</inertial>
</link>

<link name="legjointconnector2_2">
<visual>
<origin xyz="0.070232476114743036533 0.16024474380306930055 -0.028702000000000005286" rpy="-1.570796326794896558 -3.4141136496589756604e-17 -1.572791962259417777e-24" />
<geometry>
<mesh filename="package:///legjointconnector2.stl"/>
</geometry>
<material name="legjointconnector2_material">
<color rgba="0.76862745098039220171 0.88627450980392152857 0.95294117647058818044 1.0"/>
</material>
</visual>
<collision>
<origin xyz="0.070232476114743036533 0.16024474380306930055 -0.028702000000000005286" rpy="-1.570796326794896558 -3.4141136496589756604e-17 -1.572791962259417777e-24" />
<geometry>
<mesh filename="package:///legjointconnector2.stl"/>
</geometry>
</collision>
<inertial>
<origin xyz="0.061843433631572915232 0.16731335776010919369 -0.22957890588030793744" rpy="0 0 0"/>
<mass value="33.700879238921572778" />
<inertia ixx="1.8183343062068193507" ixy="-0.17203321537692875531"  ixz="-0.00026994432076550361164" iyy="1.7231385643804479901" iyz="-0.00019728284462275830257" izz="0.83789669946887124219" />
</inertial>
</link>

<link name="segment3_2">
<visual>
<origin xyz="-0.55685120142245225772 0.063499999999999640066 -0.47548799999999724619" rpy="7.9350301769323229223e-16 -1.9094820606097980998e-17 -3.141592653589793116" />
<geometry>
<mesh filename="package:///legjointconnector3.stl"/>
</geometry>
<material name="legjointconnector3_material">
<color rgba="0.81176470588235294379 0.85882352941176465233 0.89803921568627453897 1.0"/>
</material>
</visual>
<collision>
<origin xyz="-0.55685120142245225772 0.063499999999999640066 -0.47548799999999724619" rpy="7.9350301769323229223e-16 -1.9094820606097980998e-17 -3.141592653589793116" />
<geometry>
<mesh filename="package:///legjointconnector3.stl"/>
</geometry>
</collision>
<visual>
<origin xyz="-0.14843125000000023661 -0.06667500000000003979 -0.11861799999999977917" rpy="-2.4635553849666095072e-24 2.7264311370001476331e-17 4.6180341466004338256e-24" />
<geometry>
<mesh filename="package:///motor.stl"/>
</geometry>
<material name="motor_material">
<color rgba="0.64705882352941179736 0.64705882352941179736 0.64705882352941179736 1.0"/>
</material>
</visual>
<collision>
<origin xyz="-0.14843125000000023661 -0.06667500000000003979 -0.11861799999999977917" rpy="-2.4635553849666095072e-24 2.7264311370001476331e-17 4.6180341466004338256e-24" />
<geometry>
<mesh filename="package:///motor.stl"/>
</geometry>
</collision>
<visual>
<origin xyz="-1.0160711528449046792 0.066675000000000220202 -0.11861800000000022326" rpy="2.8525019787760461602e-15 -5.1394493700019338304e-17 -3.141592653589793116" />
<geometry>
<mesh filename="package:///motor.stl"/>
</geometry>
<material name="motor_material">
<color rgba="0.64705882352941179736 0.64705882352941179736 0.64705882352941179736 1.0"/>
</material>
</visual>
<collision>
<origin xyz="-1.0160711528449046792 0.066675000000000220202 -0.11861800000000022326" rpy="2.8525019787760461602e-15 -5.1394493700019338304e-17 -3.141592653589793116" />
<geometry>
<mesh filename="package:///motor.stl"/>
</geometry>
</collision>
<inertial>
<origin xyz="-0.58225120142245212485 -0.029032930571645795131 -0.24178339289668243639" rpy="0 0 0"/>
<mass value="415.11154881410027429" />
<inertia ixx="7.8602906044069982272" ixy="3.4861002973229915369e-14"  ixz="-3.6082248300317587564e-15" iyy="82.893177179424469614" iyz="-0.1227439149922755629" izz="79.382284917835818305" />
</inertial>
</link>

<link name="legjointconnector4_2">
<visual>
<origin xyz="0.066954400000000635629 -0.088900000000000006795 -0.076326999999999700641" rpy="-5.531889678106442841e-24 1.0301434282823125814e-16 -1.0616154550054563923e-24" />
<geometry>
<mesh filename="package:///legjointconnector4.stl"/>
</geometry>
<material name="legjointconnector4_material">
<color rgba="0.49803921568627451677 0.49803921568627451677 0.49803921568627451677 1.0"/>
</material>
</visual>
<collision>
<origin xyz="0.066954400000000635629 -0.088900000000000006795 -0.076326999999999700641" rpy="-5.531889678106442841e-24 1.0301434282823125814e-16 -1.0616154550054563923e-24" />
<geometry>
<mesh filename="package:///legjointconnector4.stl"/>
</geometry>
</collision>
<inertial>
<origin xyz="-0.45470653616358680527 0.0064117836026283958617 -0.22961598381417450132" rpy="0 0 0"/>
<mass value="113.67855069945751723" />
<inertia ixx="2.11032244523386181" ixy="0.31372494572636572263"  ixz="9.9897013398497020849e-07" iyy="8.909145154302921199" iyz="1.3223695423579942745e-07" izz="7.5543498430532345367" />
</inertial>
</link>

<joint name="FL_J4" type="revolute">
<origin xyz="-1.1645024028449084685 -6.5919492087118669588e-17 -8.8817841970012523234e-16" rpy="-5.3187625266587315242e-16 2.223579799404422412e-15 -9.1593406069752589358e-15" />
<parent link="segment3_2" />
<child link="legjointconnector4_2" />
<axis xyz="0 0 1"/>
<limit effort="1" velocity="20" lower="-1.0471975511965976313" upper="0.34906585039886589561"/>
<joint_properties friction="0.0"/>
</joint>

<joint name="FL_J3" type="revolute">
<origin xyz="0.20990560000000169083 0.25054560000000120068 -8.2156503822261583991e-15" rpy="1.6194871490508681314e-15 -4.0628214769688119786e-14 3.1415926535897766847" />
<parent link="legjointconnector2_2" />
<child link="segment3_2" />
<axis xyz="0 0 1"/>
<limit effort="1" velocity="20" lower="-0.1745329251994329478" upper="0.1745329251994329478"/>
<joint_properties friction="0.0"/>
</joint>

<joint name="FL_J2" type="revolute">
<origin xyz="-0.45577759999999978291 0.27635199999999815468 -0.12699999999999930789" rpy="1.570796326794896336 -1.6817628903380697032e-14 3.1415926535897527039" />
<parent link="segment1inverse" />
<child link="legjointconnector2_2" />
<axis xyz="0 0 1"/>
<limit effort="1" velocity="20" lower="-1.3962634015954635824" upper="0.52359877559829881566"/>
<joint_properties friction="0.0"/>
</joint>

<joint name="FL_J1" type="revolute">
<origin xyz="-1.2163114127589960134 -0.24146409205878277549 -0.14137120496185484608" rpy="4.1366064743825650535e-08 -1.5386514165200470003e-08 0.87266463153052575841" />
<parent link="base" />
<child link="segment1inverse" />
<axis xyz="0 0 1"/>
<limit effort="1" velocity="20" lower="-0.87266462599716476678" upper="0"/>
<joint_properties friction="0.0"/>
</joint>

<link name="segment1_2">
<visual>
<origin xyz="-0.38910259999999924352 -0.15773400000000448173 -0.27543125000000401315" rpy="1.5707963267948943376 -1.5707963267948752417 0" />
<geometry>
<mesh filename="package:///motor.stl"/>
</geometry>
<material name="motor_material">
<color rgba="0.64705882352941179736 0.64705882352941179736 0.64705882352941179736 1.0"/>
</material>
</visual>
<collision>
<origin xyz="-0.38910259999999924352 -0.15773400000000448173 -0.27543125000000401315" rpy="1.5707963267948943376 -1.5707963267948752417 0" />
<geometry>
<mesh filename="package:///motor.stl"/>
</geometry>
</collision>
<visual>
<origin xyz="0.038506400000000322315 -0.088900000000000090061 -0.45923199999999997356" rpy="1.0855553425092569471e-24 2.9854116696642350081e-24 -1.4300558256273962358e-16" />
<geometry>
<mesh filename="package:///legjointconnector1.stl"/>
</geometry>
<material name="legjointconnector1_material">
<color rgba="0.2313725490196078538 0.38039215686274507888 0.7058823529411765163 1.0"/>
</material>
</visual>
<collision>
<origin xyz="0.038506400000000322315 -0.088900000000000090061 -0.45923199999999997356" rpy="1.0855553425092569471e-24 2.9854116696642350081e-24 -1.4300558256273962358e-16" />
<geometry>
<mesh filename="package:///legjointconnector1.stl"/>
</geometry>
</collision>
<inertial>
<origin xyz="-0.40919518440973617901 -0.029508437651031237808 -0.22545957775454067429" rpy="0 0 0"/>
<mass value="188.73631876709129074" />
<inertia ixx="4.6537577933984026757" ixy="-0.25943209440132058985"  ixz="0.036542406653563584695" iyy="5.7446693413348093316" iyz="0.1666186366234777283" izz="4.0892590965831159266" />
</inertial>
</link>

<link name="legjointconnector2_3">
<visual>
<origin xyz="0.070232476114742869999 -0.16024474380306930055 -0.43052999999999996827" rpy="1.570796326794896558 5.7002955138559374851e-17 -1.1693441960770197619e-24" />
<geometry>
<mesh filename="package:///legjointconnector2.stl"/>
</geometry>
<material name="legjointconnector2_material">
<color rgba="0.76862745098039220171 0.88627450980392152857 0.95294117647058818044 1.0"/>
</material>
</visual>
<collision>
<origin xyz="0.070232476114742869999 -0.16024474380306930055 -0.43052999999999996827" rpy="1.570796326794896558 5.7002955138559374851e-17 -1.1693441960770197619e-24" />
<geometry>
<mesh filename="package:///legjointconnector2.stl"/>
</geometry>
</collision>
<inertial>
<origin xyz="0.061843433631572783393 -0.16731335776010919369 -0.22965309411969203612" rpy="0 0 0"/>
<mass value="33.700879238921572778" />
<inertia ixx="1.8183343062068193507" ixy="0.17203321537692878307"  ixz="0.0002699443207655833005" iyy="1.7231385643804484342" iyz="-0.0001972828446227622599" izz="0.83789669946887124219" />
</inertial>
</link>

<link name="segment3_3">
<visual>
<origin xyz="-0.60765120142247730506 -0.0635000000000003062 -0.47548800000000057686" rpy="-5.5331232625941850139e-14 3.3617690003015143511e-16 -1.1102171126286343959e-16" />
<geometry>
<mesh filename="package:///legjointconnector3.stl"/>
</geometry>
<material name="legjointconnector3_material">
<color rgba="0.81176470588235294379 0.85882352941176465233 0.89803921568627453897 1.0"/>
</material>
</visual>
<collision>
<origin xyz="-0.60765120142247730506 -0.0635000000000003062 -0.47548800000000057686" rpy="-5.5331232625941850139e-14 3.3617690003015143511e-16 -1.1102171126286343959e-16" />
<geometry>
<mesh filename="package:///legjointconnector3.stl"/>
</geometry>
</collision>
<visual>
<origin xyz="-1.0160711528449390961 0.066675000000000109179 -0.11861799999999966815" rpy="1.1299896492407451538e-15 -2.8277336429960771865e-16 3.141592653589793116" />
<geometry>
<mesh filename="package:///motor.stl"/>
</geometry>
<material name="motor_material">
<color rgba="0.64705882352941179736 0.64705882352941179736 0.64705882352941179736 1.0"/>
</material>
</visual>
<collision>
<origin xyz="-1.0160711528449390961 0.066675000000000109179 -0.11861799999999966815" rpy="1.1299896492407451538e-15 -2.8277336429960771865e-16 3.141592653589793116" />
<geometry>
<mesh filename="package:///motor.stl"/>
</geometry>
</collision>
<visual>
<origin xyz="-0.14843125000000001457 -0.06667500000000003979 -0.11861799999999989019" rpy="5.5318905351165507664e-24 -4.24483054551549821e-17 -1.0616707060828283524e-24" />
<geometry>
<mesh filename="package:///motor.stl"/>
</geometry>
<material name="motor_material">
<color rgba="0.64705882352941179736 0.64705882352941179736 0.64705882352941179736 1.0"/>
</material>
</visual>
<collision>
<origin xyz="-0.14843125000000001457 -0.06667500000000003979 -0.11861799999999989019" rpy="5.5318905351165507664e-24 -4.24483054551549821e-17 -1.0616707060828283524e-24" />
<geometry>
<mesh filename="package:///motor.stl"/>
</geometry>
</collision>
<inertial>
<origin xyz="-0.58225120142246966637 0.029032930571646128198 -0.24178339289668507317" rpy="0 0 0"/>
<mass value="415.11154881410027429" />
<inertia ixx="7.8602906044073490577" ixy="2.6245672302138700616e-13"  ixz="1.3489209749195651966e-13" iyy="82.893177179429642365" iyz="0.12274391499174601428" izz="79.382284917841118954" />
</inertial>
</link>

<link name="legjointconnector4_3">
<visual>
<origin xyz="0.066954399999999303361 0.088900000000000006795 -0.38290499999999982883" rpy="-3.141592653589793116 -2.6379388606249341638e-16 -1.6115813968369884017e-24" />
<geometry>
<mesh filename="package:///legjointconnector4.stl"/>
</geometry>
<material name="legjointconnector4_material">
<color rgba="0.49803921568627451677 0.49803921568627451677 0.49803921568627451677 1.0"/>
</material>
</visual>
<collision>
<origin xyz="0.066954399999999303361 0.088900000000000006795 -0.38290499999999982883" rpy="-3.141592653589793116 -2.6379388606249341638e-16 -1.6115813968369884017e-24" />
<geometry>
<mesh filename="package:///legjointconnector4.stl"/>
</geometry>
</collision>
<inertial>
<origin xyz="-0.45470653616358830407 -0.0064117836026283958617 -0.22961601618582508366" rpy="0 0 0"/>
<mass value="113.67855069945751723" />
<inertia ixx="2.1103224452338626982" ixy="-0.31372494572636577814"  ixz="-9.9897013558800843678e-07" iyy="8.909145154302921199" iyz="1.3223695418535890661e-07" izz="7.554349843053236313" />
</inertial>
</link>

<joint name="FR_J4" type="revolute">
<origin xyz="-1.1645024028449388886 1.1449174941446926823e-16 2.2204460492503130808e-16" rpy="-6.2303374567070360012e-14 -7.5210931242245077766e-14 -4.7239990430088080467e-14" />
<parent link="segment3_3" />
<child link="legjointconnector4_3" />
<axis xyz="0 0 1"/>
<limit effort="1" velocity="20" lower="-0.34906585039886589561" upper="1.0471975511965976313"/>
<joint_properties friction="0.0"/>
</joint>

<joint name="FR_J3" type="revolute">
<origin xyz="0.20990560000000030305 -0.25054559999999997943 -2.2204460492503130808e-16" rpy="1.8312212865081671257e-15 1.0372016758782980754e-15 -3.1415926535897047422" />
<parent link="legjointconnector2_3" />
<child link="segment3_3" />
<axis xyz="0 0 1"/>
<limit effort="1" velocity="20" lower="-0.1745329251994329478" upper="0.1745329251994329478"/>
<joint_properties friction="0.0"/>
</joint>

<joint name="FR_J2" type="revolute">
<origin xyz="-0.45577759999999983842 -0.27635200000000093024 -0.12700000000000108424" rpy="-1.570796326794896336 -5.0898889851839357653e-14 3.1415926535897900074" />
<parent link="segment1_2" />
<child link="legjointconnector2_3" />
<axis xyz="0 0 1"/>
<limit effort="1" velocity="20" lower="-0.52359877559829881566" upper="1.3962634015954635824"/>
<joint_properties friction="0.0"/>
</joint>

<joint name="FR_J1" type="revolute">
<origin xyz="-0.59589281598084009595 0.49792200787265827877 -0.1413711901107923552" rpy="-4.1366065395598690051e-08 1.5386515297447615188e-08 -2.2689280220592671355" />
<parent link="base" />
<child link="segment1_2" />
<axis xyz="0 0 1"/>
<limit effort="1" velocity="20" lower="0" upper="0.87266462599716476678"/>
<joint_properties friction="0.0"/>
</joint>

<link name="segment1inverse_2">
<visual>
<origin xyz="-0.52245259999999960066 0.15773400000000015186 -0.27543125000000001634" rpy="-1.5707963267948970021 -1.570796326794896336 0" />
<geometry>
<mesh filename="package:///motor.stl"/>
</geometry>
<material name="motor_material">
<color rgba="0.64705882352941179736 0.64705882352941179736 0.64705882352941179736 1.0"/>
</material>
</visual>
<collision>
<origin xyz="-0.52245259999999960066 0.15773400000000015186 -0.27543125000000001634" rpy="-1.5707963267948970021 -1.570796326794896336 0" />
<geometry>
<mesh filename="package:///motor.stl"/>
</geometry>
</collision>
<visual>
<origin xyz="0.038506400000000273742 -0.088899999999999979039 -0.45923199999999997356" rpy="3.6532230084497073701e-24 -4.3107955582977604979e-25 -1.5490333779596078233e-17" />
<geometry>
<mesh filename="package:///legjointconnector1.stl"/>
</geometry>
<material name="legjointconnector1_material">
<color rgba="0.2313725490196078538 0.38039215686274507888 0.7058823529411765163 1.0"/>
</material>
</visual>
<collision>
<origin xyz="0.038506400000000273742 -0.088899999999999979039 -0.45923199999999997356" rpy="3.6532230084497073701e-24 -4.3107955582977604979e-25 -1.5490333779596078233e-17" />
<geometry>
<mesh filename="package:///legjointconnector1.stl"/>
</geometry>
</collision>
<inertial>
<origin xyz="-0.40919518440973617901 0.029508437651028434495 -0.22545957775453856486" rpy="0 0 0"/>
<mass value="188.73631876709129074" />
<inertia ixx="4.6537577933983582668" ixy="0.25943209440128711663"  ixz="0.036542406653598522026" iyy="5.7446693413348253188" iyz="-0.16661863662344703063" izz="4.0892590965830573069" />
</inertial>
</link>

<link name="legjointconnector2_4">
<visual>
<origin xyz="0.070232476114742814488 0.1602447438030693283 -0.028702000000000060798" rpy="-1.570796326794896558 -5.2296284388309159776e-17 -1.7724988333260274585e-24" />
<geometry>
<mesh filename="package:///legjointconnector2.stl"/>
</geometry>
<material name="legjointconnector2_material">
<color rgba="0.76862745098039220171 0.88627450980392152857 0.95294117647058818044 1.0"/>
</material>
</visual>
<collision>
<origin xyz="0.070232476114742814488 0.1602447438030693283 -0.028702000000000060798" rpy="-1.570796326794896558 -5.2296284388309159776e-17 -1.7724988333260274585e-24" />
<geometry>
<mesh filename="package:///legjointconnector2.stl"/>
</geometry>
</collision>
<inertial>
<origin xyz="0.06184343363157267931 0.16731335776010922145 -0.2295789058803080207" rpy="0 0 0"/>
<mass value="33.700879238921572778" />
<inertia ixx="1.8183343062068202389" ixy="-0.17203321537692881082"  ixz="-0.00026994432076545205783" iyy="1.7231385643804484342" iyz="-0.00019728284462276147386" izz="0.83789669946887146423" />
</inertial>
</link>

<link name="segment3_4">
<visual>
<origin xyz="-0.55685120142245525532 0.063500000000001902145 -0.47548800000001789634" rpy="-5.4571626714110350515e-14 3.7957708199438077792e-14 3.141592653589793116" />
<geometry>
<mesh filename="package:///legjointconnector3.stl"/>
</geometry>
<material name="legjointconnector3_material">
<color rgba="0.81176470588235294379 0.85882352941176465233 0.89803921568627453897 1.0"/>
</material>
</visual>
<collision>
<origin xyz="-0.55685120142245525532 0.063500000000001902145 -0.47548800000001789634" rpy="-5.4571626714110350515e-14 3.7957708199438077792e-14 3.141592653589793116" />
<geometry>
<mesh filename="package:///legjointconnector3.stl"/>
</geometry>
</collision>
<visual>
<origin xyz="-0.14843125000000001457 -0.066675000000000025913 -0.11861799999999989019" rpy="6.4489667598316965425e-24 -1.3616016588760725695e-17 -3.6437351229119743003e-24" />
<geometry>
<mesh filename="package:///motor.stl"/>
</geometry>
<material name="motor_material">
<color rgba="0.64705882352941179736 0.64705882352941179736 0.64705882352941179736 1.0"/>
</material>
</visual>
<collision>
<origin xyz="-0.14843125000000001457 -0.066675000000000025913 -0.11861799999999989019" rpy="6.4489667598316965425e-24 -1.3616016588760725695e-17 -3.6437351229119743003e-24" />
<geometry>
<mesh filename="package:///motor.stl"/>
</geometry>
</collision>
<visual>
<origin xyz="-1.0160711528449088981 0.066674999999999456923 -0.1186180000000268131" rpy="-5.9400693104967926781e-14 3.1405900234355128248e-16 -3.141592653589793116" />
<geometry>
<mesh filename="package:///motor.stl"/>
</geometry>
<material name="motor_material">
<color rgba="0.64705882352941179736 0.64705882352941179736 0.64705882352941179736 1.0"/>
</material>
</visual>
<collision>
<origin xyz="-1.0160711528449088981 0.066674999999999456923 -0.1186180000000268131" rpy="-5.9400693104967926781e-14 3.1405900234355128248e-16 -3.141592653589793116" />
<geometry>
<mesh filename="package:///motor.stl"/>
</geometry>
</collision>
<inertial>
<origin xyz="-0.58225120142245445631 -0.029032930571646825557 -0.2417833928967009216" rpy="0 0 0"/>
<mass value="415.11154881410027429" />
<inertia ixx="7.8602906044071492175" ixy="-8.2822637637036677916e-14"  ixz="-1.9356183322827291704e-12" iyy="82.893177179426146495" iyz="-0.12274391499159888197" izz="79.382284917837267813" />
</inertial>
</link>

<link name="legjointconnector4_4">
<visual>
<origin xyz="0.066954399999999969495 -0.088899999999999992917 -0.076326999999999867175" rpy="5.175406299591749267e-24 -1.4487980908781379142e-17 2.0768451985318374506e-26" />
<geometry>
<mesh filename="package:///legjointconnector4.stl"/>
</geometry>
<material name="legjointconnector4_material">
<color rgba="0.49803921568627451677 0.49803921568627451677 0.49803921568627451677 1.0"/>
</material>
</visual>
<collision>
<origin xyz="0.066954399999999969495 -0.088899999999999992917 -0.076326999999999867175" rpy="5.175406299591749267e-24 -1.4487980908781379142e-17 2.0768451985318374506e-26" />
<geometry>
<mesh filename="package:///legjointconnector4.stl"/>
</geometry>
</collision>
<inertial>
<origin xyz="-0.4547065361635874714 0.0064117836026284097395 -0.22961598381417475112" rpy="0 0 0"/>
<mass value="113.67855069945751723" />
<inertia ixx="2.11032244523386181" ixy="0.31372494572636572263"  ixz="9.9897013343142697768e-07" iyy="8.909145154302921199" iyz="1.3223695427266285718e-07" izz="7.554349843053236313" />
</inertial>
</link>

<joint name="BR_J4" type="revolute">
<origin xyz="-1.1645024028449117992 -3.8163916471489756077e-17 -3.1363800445660672267e-14" rpy="1.1607104557275275595e-14 -1.317684822795214061e-14 1.7097434238094243648e-14" />
<parent link="segment3_4" />
<child link="legjointconnector4_4" />
<axis xyz="0 0 1"/>
<limit effort="1" velocity="20" lower="-1.0471975511965976313" upper="0.34906585039886589561"/>
<joint_properties friction="0.0"/>
</joint>

<joint name="BR_J3" type="revolute">
<origin xyz="0.2099056000000000255 0.25054559999999997943 -1.1102230246251565404e-16" rpy="-2.4583537112042395624e-14 1.7733630015494619918e-14 3.1415926535897771288" />
<parent link="legjointconnector2_4" />
<child link="segment3_4" />
<axis xyz="0 0 1"/>
<limit effort="1" velocity="20" lower="-0.1745329251994329478" upper="0.1745329251994329478"/>
<joint_properties friction="0.0"/>
</joint>

<joint name="BR_J2" type="revolute">
<origin xyz="-0.45577759999999961638 0.27635199999999993103 -0.12699999999999991851" rpy="1.570796326794896336 2.5617351588273872295e-15 -3.1415926535897726879" />
<parent link="segment1inverse_2" />
<child link="legjointconnector2_4" />
<axis xyz="0 0 1"/>
<limit effort="1" velocity="20" lower="-1.3962634015954635824" upper="0.52359877559829881566"/>
<joint_properties friction="0.0"/>
</joint>

<joint name="BR_J1" type="revolute">
<origin xyz="0.096795214481245284155 -0.083312256477406296251 -0.14137122751564284995" rpy="-4.1366066429508016595e-08 1.5386513625598157424e-08 -2.2689280220592662474" />
<parent link="base" />
<child link="segment1inverse_2" />
<axis xyz="0 0 1"/>
<limit effort="1" velocity="20" lower="-0.87266462599716476678" upper="0"/>
<joint_properties friction="0.0"/>
</joint>


</robot>
