<robot name="onshape">
<link name="base">
<visual>
<origin xyz="-0.68018618325141355641 -0.77836459757771037093 -0.2599892372525848816" rpy="1.5386514007653082967e-08 4.136606557689327442e-08 -0.69813169526437079959" />
<geometry>
<mesh filename="package:///motor.stl"/>
</geometry>
<material name="motor_material">
<color rgba="0.64705882352941179736 0.64705882352941179736 0.64705882352941179736 1.0"/>
</material>
</visual>
<collision>
<origin xyz="-0.68018618325141355641 -0.77836459757771037093 -0.2599892372525848816" rpy="1.5386514007653082967e-08 4.136606557689327442e-08 -0.69813169526437079959" />
<geometry>
<mesh filename="package:///motor.stl"/>
</geometry>
</collision>
<visual>
<origin xyz="-1.0597486169757592833 -0.28579784178566564057 -0.25998921007597636246" rpy="-1.5386514165201171452e-08 -4.1366064709380387372e-08 2.4434609583254234266" />
<geometry>
<mesh filename="package:///motor.stl"/>
</geometry>
<material name="motor_material">
<color rgba="0.64705882352941179736 0.64705882352941179736 0.64705882352941179736 1.0"/>
</material>
</visual>
<collision>
<origin xyz="-1.0597486169757592833 -0.28579784178566564057 -0.25998921007597636246" rpy="-1.5386514165201171452e-08 -4.1366064709380387372e-08 2.4434609583254234266" />
<geometry>
<mesh filename="package:///motor.stl"/>
</geometry>
</collision>
<visual>
<origin xyz="-0.059767586473256535673 -0.038978497646272099175 -0.25998922240152178009" rpy="1.5386513844399099308e-08 4.1366065512371697716e-08 -0.69813169526437102164" />
<geometry>
<mesh filename="package:///motor.stl"/>
</geometry>
<material name="motor_material">
<color rgba="0.64705882352941179736 0.64705882352941179736 0.64705882352941179736 1.0"/>
</material>
</visual>
<collision>
<origin xyz="-0.059767586473256535673 -0.038978497646272099175 -0.25998922240152178009" rpy="1.5386513844399099308e-08 4.1366065512371697716e-08 -0.69813169526437102164" />
<geometry>
<mesh filename="package:///motor.stl"/>
</geometry>
</collision>
<visual>
<origin xyz="-0.77661850693285938707 -0.33686214394097313551 -0.28437321820730343536" rpy="-1.5707963114083824951 4.136606507362698783e-08 -0.69813169526436991141" />
<geometry>
<mesh filename="package:///baseplate.stl"/>
</geometry>
<material name="baseplate_material">
<color rgba="0.43921568627450979783 0.47450980392156860699 0.50196078431372548323 1.0"/>
</material>
</visual>
<collision>
<origin xyz="-0.77661850693285938707 -0.33686214394097313551 -0.28437321820730343536" rpy="-1.5707963114083824951 4.136606507362698783e-08 -0.69813169526436991141" />
<geometry>
<mesh filename="package:///baseplate.stl"/>
</geometry>
</collision>
<visual>
<origin xyz="-0.43933002019760314383 0.4535882581457729712 -0.25998919522491303891" rpy="-1.5386514229975246692e-08 -4.1366064456472866465e-08 2.4434609583254229825" />
<geometry>
<mesh filename="package:///motor.stl"/>
</geometry>
<material name="motor_material">
<color rgba="0.64705882352941179736 0.64705882352941179736 0.64705882352941179736 1.0"/>
</material>
</visual>
<collision>
<origin xyz="-0.43933002019760314383 0.4535882581457729712 -0.25998919522491303891" rpy="-1.5386514229975246692e-08 -4.1366064456472866465e-08 2.4434609583254229825" />
<geometry>
<mesh filename="package:///motor.stl"/>
</geometry>
</collision>
<inertial>
<origin xyz="-0.55889969120758575816 -0.16281071528719956443 -0.43853106493353538609" rpy="0 0 0"/>
<mass value="1406.2088699182113487" />
<inertia ixx="229.76847627583339317" ixy="25.688424731455100414"  ixz="0.86795743367190103523" iyy="238.76229640209703575" iyz="-0.75828716275290819482" izz="410.74917094328247913" />
</inertial>
</link>

<link name="segment1">
<visual>
<origin xyz="-0.38910259999999996516 -0.15773399999999973553 -0.27543124999999840652" rpy="1.5707963267948947816 -1.570796326794896336 0" />
<geometry>
<mesh filename="package:///motor.stl"/>
</geometry>
<material name="motor_material">
<color rgba="0.64705882352941179736 0.64705882352941179736 0.64705882352941179736 1.0"/>
</material>
</visual>
<collision>
<origin xyz="-0.38910259999999996516 -0.15773399999999973553 -0.27543124999999840652" rpy="1.5707963267948947816 -1.570796326794896336 0" />
<geometry>
<mesh filename="package:///motor.stl"/>
</geometry>
</collision>
<visual>
<origin xyz="0.038506400000000384765 -0.088899999999999951283 -0.45923199999999991805" rpy="-2.3594425463589673839e-24 -2.6299558701564584806e-24 -1.7276370907223099977e-17" />
<geometry>
<mesh filename="package:///legjointconnector1.stl"/>
</geometry>
<material name="legjointconnector1_material">
<color rgba="0.2313725490196078538 0.38039215686274507888 0.7058823529411765163 1.0"/>
</material>
</visual>
<collision>
<origin xyz="0.038506400000000384765 -0.088899999999999951283 -0.45923199999999991805" rpy="-2.3594425463589673839e-24 -2.6299558701564584806e-24 -1.7276370907223099977e-17" />
<geometry>
<mesh filename="package:///legjointconnector1.stl"/>
</geometry>
</collision>
<inertial>
<origin xyz="-0.40919518440973634554 -0.029508437651028687765 -0.22545957775453764893" rpy="0 0 0"/>
<mass value="188.73631876709129074" />
<inertia ixx="4.6537577933983360623" ixy="-0.25943209440129805232"  ixz="0.036542406653606210321" iyy="5.7446693413347995616" iyz="0.16661863662344597592" izz="4.0892590965830404315" />
</inertial>
</link>

<link name="legjointconnector2">
<visual>
<origin xyz="0.070232476114742814488 -0.16024474380306930055 -0.43053000000000002379" rpy="1.570796326794896558 5.23849986713375207e-17 4.1548090572940437965e-24" />
<geometry>
<mesh filename="package:///legjointconnector2.stl"/>
</geometry>
<material name="legjointconnector2_material">
<color rgba="0.76862745098039220171 0.88627450980392152857 0.95294117647058818044 1.0"/>
</material>
</visual>
<collision>
<origin xyz="0.070232476114742814488 -0.16024474380306930055 -0.43053000000000002379" rpy="1.570796326794896558 5.23849986713375207e-17 4.1548090572940437965e-24" />
<geometry>
<mesh filename="package:///legjointconnector2.stl"/>
</geometry>
</collision>
<inertial>
<origin xyz="0.061843433631572665432 -0.16731335776010919369 -0.22965309411969209163" rpy="0 0 0"/>
<mass value="33.700879238921558567" />
<inertia ixx="1.8183343062068200169" ixy="0.17203321537692889409"  ixz="0.00026994432076554513659" iyy="1.7231385643804477681" iyz="-0.00019728284462275751652" izz="0.83789669946887124219" />
</inertial>
</link>

<link name="segment3">
<visual>
<origin xyz="-0.60765120142246087376 -0.063500000000000514366 -0.47548799999999413757" rpy="1.0265558900359157039e-14 1.018869085839037601e-14 4.4408860272122942354e-16" />
<geometry>
<mesh filename="package:///legjointconnector3.stl"/>
</geometry>
<material name="legjointconnector3_material">
<color rgba="0.81176470588235294379 0.85882352941176465233 0.89803921568627453897 1.0"/>
</material>
</visual>
<collision>
<origin xyz="-0.60765120142246087376 -0.063500000000000514366 -0.47548799999999413757" rpy="1.0265558900359157039e-14 1.018869085839037601e-14 4.4408860272122942354e-16" />
<geometry>
<mesh filename="package:///legjointconnector3.stl"/>
</geometry>
</collision>
<visual>
<origin xyz="-1.0160711528449153374 0.066674999999998055267 -0.11861799999999173005" rpy="-1.5700470015193580254e-14 -1.5114195353652143769e-14 -3.141592653589793116" />
<geometry>
<mesh filename="package:///motor.stl"/>
</geometry>
<material name="motor_material">
<color rgba="0.64705882352941179736 0.64705882352941179736 0.64705882352941179736 1.0"/>
</material>
</visual>
<collision>
<origin xyz="-1.0160711528449153374 0.066674999999998055267 -0.11861799999999173005" rpy="-1.5700470015193580254e-14 -1.5114195353652143769e-14 -3.141592653589793116" />
<geometry>
<mesh filename="package:///motor.stl"/>
</geometry>
</collision>
<visual>
<origin xyz="-0.14843125000000023661 -0.066675000000000012035 -0.11861800000000005673" rpy="-1.016652221848880541e-23 -7.979130930031470155e-17 -4.9413390326145392261e-24" />
<geometry>
<mesh filename="package:///motor.stl"/>
</geometry>
<material name="motor_material">
<color rgba="0.64705882352941179736 0.64705882352941179736 0.64705882352941179736 1.0"/>
</material>
</visual>
<collision>
<origin xyz="-0.14843125000000023661 -0.066675000000000012035 -0.11861800000000005673" rpy="-1.016652221848880541e-23 -7.979130930031470155e-17 -4.9413390326145392261e-24" />
<geometry>
<mesh filename="package:///motor.stl"/>
</geometry>
</collision>
<inertial>
<origin xyz="-0.58225120142245767596 0.029032930571645961665 -0.24178339289667888368" rpy="0 0 0"/>
<mass value="415.11154881410027429" />
<inertia ixx="7.8602906044070941505" ixy="4.283240429003853933e-13"  ixz="4.8067105851146152418e-13" iyy="82.893177179426444923" iyz="0.12274391499240175363" izz="79.382284917837822036" />
</inertial>
</link>

<link name="legjointconnector4">
<visual>
<origin xyz="0.066954400000000635629 0.088900000000000020672 -0.38290500000000038394" rpy="3.141592653589793116 -1.9204029201404763788e-16 -3.4968873218668733862e-24" />
<geometry>
<mesh filename="package:///legjointconnector4.stl"/>
</geometry>
<material name="legjointconnector4_material">
<color rgba="0.49803921568627451677 0.49803921568627451677 0.49803921568627451677 1.0"/>
</material>
</visual>
<collision>
<origin xyz="0.066954400000000635629 0.088900000000000020672 -0.38290500000000038394" rpy="3.141592653589793116 -1.9204029201404763788e-16 -3.4968873218668733862e-24" />
<geometry>
<mesh filename="package:///legjointconnector4.stl"/>
</geometry>
</collision>
<inertial>
<origin xyz="-0.45470653616358702731 -0.0064117836026283958617 -0.22961601618582558326" rpy="0 0 0"/>
<mass value="113.67855069945754565" />
<inertia ixx="2.1103224452338631423" ixy="-0.31372494572636588916"  ixz="-9.9897013439377541389e-07" iyy="8.909145154302921199" iyz="1.3223695421246390798e-07" izz="7.5543498430532398658" />
</inertial>
</link>

<joint name="BL_J4" type="revolute">
<origin xyz="-1.1645024028449160181 -1.3877787807814456755e-17 9.7144514654701197287e-15" rpy="-1.0002491849452616732e-14 -1.8279819730990857957e-14 2.5535131700721312462e-15" />
<parent link="segment3" />
<child link="legjointconnector4" />
<axis xyz="0 0 1"/>
<limit effort="1" velocity="20" lower="-0.34906585039886589561" upper="1.0471975511965976313"/>
<joint_properties friction="0.0"/>
</joint>

<joint name="BL_J3" type="revolute">
<origin xyz="0.20990560000000035856 -0.25054559999999992392 0" rpy="-2.5283167277087328215e-15 3.1919323348587798512e-15 3.1415926535897922278" />
<parent link="legjointconnector2" />
<child link="segment3" />
<axis xyz="0 0 1"/>
<limit effort="1" velocity="20" lower="-0.1745329251994329478" upper="0.1745329251994329478"/>
<joint_properties friction="0.0"/>
</joint>

<joint name="BL_J2" type="revolute">
<origin xyz="-0.45577759999999978291 -0.27635199999999915388 -0.12699999999999922462" rpy="-1.570796326794896336 -1.1133486160753729077e-16 -3.1415926535897860106" />
<parent link="segment1" />
<child link="legjointconnector2" />
<axis xyz="0 0 1"/>
<limit effort="1" velocity="20" lower="-0.52359877559829881566" upper="1.3962634015954635824"/>
<joint_properties friction="0.0"/>
</joint>

<joint name="BL_J1" type="revolute">
<origin xyz="-0.52362338229691240965 -0.82269835640884436678 -0.14137124236670622901" rpy="4.1366065576892837669e-08 -1.5386514007654697624e-08 0.87266463153052697965" />
<parent link="base" />
<child link="segment1" />
<axis xyz="0 0 1"/>
<limit effort="1" velocity="20" lower="0" upper="0.87266462599716476678"/>
<joint_properties friction="0.0"/>
</joint>

<link name="segment1inverse">
<visual>
<origin xyz="-0.52245259999999960066 0.1577339999999998188 -0.27543124999999801794" rpy="-1.5707963267948934494 -1.5707963267948961139 0" />
<geometry>
<mesh filename="package:///motor.stl"/>
</geometry>
<material name="motor_material">
<color rgba="0.64705882352941179736 0.64705882352941179736 0.64705882352941179736 1.0"/>
</material>
</visual>
<collision>
<origin xyz="-0.52245259999999960066 0.1577339999999998188 -0.27543124999999801794" rpy="-1.5707963267948934494 -1.5707963267948961139 0" />
<geometry>
<mesh filename="package:///motor.stl"/>
</geometry>
</collision>
<visual>
<origin xyz="0.03850640000000016272 -0.088899999999999979039 -0.45923199999999986254" rpy="1.0013444732289341124e-24 1.6486979533615037228e-24 -4.9928761440132623273e-17" />
<geometry>
<mesh filename="package:///legjointconnector1.stl"/>
</geometry>
<material name="legjointconnector1_material">
<color rgba="0.2313725490196078538 0.38039215686274507888 0.7058823529411765163 1.0"/>
</material>
</visual>
<collision>
<origin xyz="0.03850640000000016272 -0.088899999999999979039 -0.45923199999999986254" rpy="1.0013444732289341124e-24 1.6486979533615037228e-24 -4.9928761440132623273e-17" />
<geometry>
<mesh filename="package:///legjointconnector1.stl"/>
</geometry>
</collision>
<inertial>
<origin xyz="-0.40919518440973745577 0.029508437651029319204 -0.22545957775453739913" rpy="0 0 0"/>
<mass value="188.73631876709129074" />
<inertia ixx="4.65375779339823481" ixy="0.25943209440130843291"  ixz="0.036542406653607674427" iyy="5.7446693413348022261" iyz="-0.16661863662344592041" izz="4.0892590965830537542" />
</inertial>
</link>

<link name="legjointconnector2_2">
<visual>
<origin xyz="0.070232476114742814488 0.16024474380306927279 -0.028702000000000227331" rpy="-1.570796326794896558 5.8508240830970642532e-17 2.1393347536805987152e-24" />
<geometry>
<mesh filename="package:///legjointconnector2.stl"/>
</geometry>
<material name="legjointconnector2_material">
<color rgba="0.76862745098039220171 0.88627450980392152857 0.95294117647058818044 1.0"/>
</material>
</visual>
<collision>
<origin xyz="0.070232476114742814488 0.16024474380306927279 -0.028702000000000227331" rpy="-1.570796326794896558 5.8508240830970642532e-17 2.1393347536805987152e-24" />
<geometry>
<mesh filename="package:///legjointconnector2.stl"/>
</geometry>
</collision>
<inertial>
<origin xyz="0.061843433631572637676 0.16731335776010916594 -0.22957890588030824275" rpy="0 0 0"/>
<mass value="33.700879238921558567" />
<inertia ixx="1.8183343062068191287" ixy="-0.17203321537692886634"  ixz="-0.00026994432076561387501" iyy="1.7231385643804477681" iyz="-0.00019728284462273848877" izz="0.83789669946887190832" />
</inertial>
</link>

<link name="segment3_2">
<visual>
<origin xyz="-0.55685120142244759478 0.063499999999999001687 -0.4754879999999948037" rpy="7.5858816515377255932e-15 -7.7432306988090543971e-17 3.141592653589793116" />
<geometry>
<mesh filename="package:///legjointconnector3.stl"/>
</geometry>
<material name="legjointconnector3_material">
<color rgba="0.81176470588235294379 0.85882352941176465233 0.89803921568627453897 1.0"/>
</material>
</visual>
<collision>
<origin xyz="-0.55685120142244759478 0.063499999999999001687 -0.4754879999999948037" rpy="7.5858816515377255932e-15 -7.7432306988090543971e-17 3.141592653589793116" />
<geometry>
<mesh filename="package:///legjointconnector3.stl"/>
</geometry>
</collision>
<visual>
<origin xyz="-0.14843125000000001457 -0.06667500000000003979 -0.11861800000000000122" rpy="-1.9628924208515406731e-24 6.2282236768544246245e-17 -2.8294243199582598685e-24" />
<geometry>
<mesh filename="package:///motor.stl"/>
</geometry>
<material name="motor_material">
<color rgba="0.64705882352941179736 0.64705882352941179736 0.64705882352941179736 1.0"/>
</material>
</visual>
<collision>
<origin xyz="-0.14843125000000001457 -0.06667500000000003979 -0.11861800000000000122" rpy="-1.9628924208515406731e-24 6.2282236768544246245e-17 -2.8294243199582598685e-24" />
<geometry>
<mesh filename="package:///motor.stl"/>
</geometry>
</collision>
<visual>
<origin xyz="-1.0160711528448964636 0.066674999999999373657 -0.11861800000000000122" rpy="6.6662858937753126218e-16 1.3660493144232699117e-16 -3.141592653589793116" />
<geometry>
<mesh filename="package:///motor.stl"/>
</geometry>
<material name="motor_material">
<color rgba="0.64705882352941179736 0.64705882352941179736 0.64705882352941179736 1.0"/>
</material>
</visual>
<collision>
<origin xyz="-1.0160711528448964636 0.066674999999999373657 -0.11861800000000000122" rpy="6.6662858937753126218e-16 1.3660493144232699117e-16 -3.141592653589793116" />
<geometry>
<mesh filename="package:///motor.stl"/>
</geometry>
</collision>
<inertial>
<origin xyz="-0.58225120142244823906 -0.029032930571645448187 -0.24178339289668168699" rpy="0 0 0"/>
<mass value="415.11154881410027429" />
<inertia ixx="7.8602906044068516778" ixy="9.2814644858663086779e-14"  ixz="9.6977981201007423806e-14" iyy="82.893177179423219059" iyz="-0.12274391499233144875" izz="79.382284917834624594" />
</inertial>
</link>

<link name="legjointconnector4_2">
<visual>
<origin xyz="0.06695439999999974745 -0.088900000000000020672 -0.076326999999999922686" rpy="9.1740366866591828477e-25 1.1931985301723232982e-17 -4.2634012274671713725e-25" />
<geometry>
<mesh filename="package:///legjointconnector4.stl"/>
</geometry>
<material name="legjointconnector4_material">
<color rgba="0.49803921568627451677 0.49803921568627451677 0.49803921568627451677 1.0"/>
</material>
</visual>
<collision>
<origin xyz="0.06695439999999974745 -0.088900000000000020672 -0.076326999999999922686" rpy="9.1740366866591828477e-25 1.1931985301723232982e-17 -4.2634012274671713725e-25" />
<geometry>
<mesh filename="package:///legjointconnector4.stl"/>
</geometry>
</collision>
<inertial>
<origin xyz="-0.45470653616358791549 0.0064117836026283958617 -0.22961598381417477888" rpy="0 0 0"/>
<mass value="113.67855069945754565" />
<inertia ixx="2.1103224452338631423" ixy="0.31372494572636588916"  ixz="9.989701341119601408e-07" iyy="8.909145154302921199" iyz="1.3223695426896833769e-07" izz="7.5543498430532345367" />
</inertial>
</link>

<joint name="FL_J4" type="revolute">
<origin xyz="-1.1645024028448953679 -7.9797279894933126343e-17 -1.9984014443252817728e-15" rpy="-1.4230303722337115841e-14 1.0989215082908320336e-14 -1.9142660398205388481e-22" />
<parent link="segment3_2" />
<child link="legjointconnector4_2" />
<axis xyz="0 0 1"/>
<limit effort="1" velocity="20" lower="-1.0471975511965976313" upper="0.34906585039886589561"/>
<joint_properties friction="0.0"/>
</joint>

<joint name="FL_J3" type="revolute">
<origin xyz="0.20990560000000035856 0.25054559999999992392 0" rpy="1.0838683866018271256e-15 -4.2368862056886156146e-15 -3.1415926535897842342" />
<parent link="legjointconnector2_2" />
<child link="segment3_2" />
<axis xyz="0 0 1"/>
<limit effort="1" velocity="20" lower="-0.1745329251994329478" upper="0.1745329251994329478"/>
<joint_properties friction="0.0"/>
</joint>

<joint name="FL_J2" type="revolute">
<origin xyz="-0.45577759999999978291 0.27635199999999837672 -0.12699999999999925238" rpy="1.570796326794896336 8.4958856427445189586e-15 3.1415926535897917837" />
<parent link="segment1inverse" />
<child link="legjointconnector2_2" />
<axis xyz="0 0 1"/>
<limit effort="1" velocity="20" lower="-1.3962634015954635824" upper="0.52359877559829881566"/>
<joint_properties friction="0.0"/>
</joint>

<joint name="FL_J1" type="revolute">
<origin xyz="-1.2163114127589960134 -0.24146409205878277549 -0.14137120496185484608" rpy="4.1366064743825650535e-08 -1.5386514165200470003e-08 0.87266463153052575841" />
<parent link="base" />
<child link="segment1inverse" />
<axis xyz="0 0 1"/>
<limit effort="1" velocity="20" lower="-0.87266462599716476678" upper="0"/>
<joint_properties friction="0.0"/>
</joint>

<link name="segment1_2">
<visual>
<origin xyz="-0.38910259999999924352 -0.15773400000000448173 -0.27543125000000401315" rpy="1.5707963267948943376 -1.5707963267948752417 0" />
<geometry>
<mesh filename="package:///motor.stl"/>
</geometry>
<material name="motor_material">
<color rgba="0.64705882352941179736 0.64705882352941179736 0.64705882352941179736 1.0"/>
</material>
</visual>
<collision>
<origin xyz="-0.38910259999999924352 -0.15773400000000448173 -0.27543125000000401315" rpy="1.5707963267948943376 -1.5707963267948752417 0" />
<geometry>
<mesh filename="package:///motor.stl"/>
</geometry>
</collision>
<visual>
<origin xyz="0.038506400000000322315 -0.088900000000000090061 -0.45923199999999997356" rpy="1.0855553425092569471e-24 2.9854116696642350081e-24 -1.4300558256273962358e-16" />
<geometry>
<mesh filename="package:///legjointconnector1.stl"/>
</geometry>
<material name="legjointconnector1_material">
<color rgba="0.2313725490196078538 0.38039215686274507888 0.7058823529411765163 1.0"/>
</material>
</visual>
<collision>
<origin xyz="0.038506400000000322315 -0.088900000000000090061 -0.45923199999999997356" rpy="1.0855553425092569471e-24 2.9854116696642350081e-24 -1.4300558256273962358e-16" />
<geometry>
<mesh filename="package:///legjointconnector1.stl"/>
</geometry>
</collision>
<inertial>
<origin xyz="-0.40919518440973617901 -0.029508437651031234339 -0.22545957775454070204" rpy="0 0 0"/>
<mass value="188.73631876709129074" />
<inertia ixx="4.6537577933984035639" ixy="-0.25943209440132070087"  ixz="0.036542406653563598573" iyy="5.7446693413348102197" iyz="0.16661863662347778381" izz="4.0892590965831168148" />
</inertial>
</link>

<link name="legjointconnector2_3">
<visual>
<origin xyz="0.07023247611474292551 -0.16024474380306927279 -0.43052999999999996827" rpy="1.570796326794896558 -1.1912119692000964032e-17 -4.7691918460501830393e-24" />
<geometry>
<mesh filename="package:///legjointconnector2.stl"/>
</geometry>
<material name="legjointconnector2_material">
<color rgba="0.76862745098039220171 0.88627450980392152857 0.95294117647058818044 1.0"/>
</material>
</visual>
<collision>
<origin xyz="0.07023247611474292551 -0.16024474380306927279 -0.43052999999999996827" rpy="1.570796326794896558 -1.1912119692000964032e-17 -4.7691918460501830393e-24" />
<geometry>
<mesh filename="package:///legjointconnector2.stl"/>
</geometry>
</collision>
<inertial>
<origin xyz="0.06184343363157274176 -0.16731335776010916594 -0.22965309411969200837" rpy="0 0 0"/>
<mass value="33.700879238921558567" />
<inertia ixx="1.8183343062068191287" ixy="0.17203321537692886634"  ixz="0.00026994432076557294637" iyy="1.7231385643804477681" iyz="-0.00019728284462274645766" izz="0.83789669946887146423" />
</inertial>
</link>

<link name="segment3_3">
<visual>
<origin xyz="-0.60765120142248307822 -0.063500000000000556 -0.47548799999999979971" rpy="-8.9166951304726239289e-14 -4.4665810913597363172e-17 5.8631573281378512549e-24" />
<geometry>
<mesh filename="package:///legjointconnector3.stl"/>
</geometry>
<material name="legjointconnector3_material">
<color rgba="0.81176470588235294379 0.85882352941176465233 0.89803921568627453897 1.0"/>
</material>
</visual>
<collision>
<origin xyz="-0.60765120142248307822 -0.063500000000000556 -0.47548799999999979971" rpy="-8.9166951304726239289e-14 -4.4665810913597363172e-17 5.8631573281378512549e-24" />
<geometry>
<mesh filename="package:///legjointconnector3.stl"/>
</geometry>
</collision>
<visual>
<origin xyz="-1.0160711528449370977 0.066675000000000192446 -0.11861800000000233268" rpy="3.5015750566735597494e-14 1.0852977972759618269e-17 -3.141592653589793116" />
<geometry>
<mesh filename="package:///motor.stl"/>
</geometry>
<material name="motor_material">
<color rgba="0.64705882352941179736 0.64705882352941179736 0.64705882352941179736 1.0"/>
</material>
</visual>
<collision>
<origin xyz="-1.0160711528449370977 0.066675000000000192446 -0.11861800000000233268" rpy="3.5015750566735597494e-14 1.0852977972759618269e-17 -3.141592653589793116" />
<geometry>
<mesh filename="package:///motor.stl"/>
</geometry>
</collision>
<visual>
<origin xyz="-0.14843124999999990354 -0.066675000000000012035 -0.11861800000000000122" rpy="5.2395689382779232315e-24 1.2736790126255040239e-17 5.8631573281389069958e-24" />
<geometry>
<mesh filename="package:///motor.stl"/>
</geometry>
<material name="motor_material">
<color rgba="0.64705882352941179736 0.64705882352941179736 0.64705882352941179736 1.0"/>
</material>
</visual>
<collision>
<origin xyz="-0.14843124999999990354 -0.066675000000000012035 -0.11861800000000000122" rpy="5.2395689382779232315e-24 1.2736790126255040239e-17 5.8631573281389069958e-24" />
<geometry>
<mesh filename="package:///motor.stl"/>
</geometry>
</collision>
<inertial>
<origin xyz="-0.58225120142246988841 0.029032930571646145546 -0.24178339289668659973" rpy="0 0 0"/>
<mass value="415.11154881410027429" />
<inertia ixx="7.8602906044073446168" ixy="4.283240429003853933e-13"  ixz="2.5363044997561701166e-13" iyy="82.893177179429841317" iyz="0.12274391499132650263" izz="79.382284917841275274" />
</inertial>
</link>

<link name="legjointconnector4_3">
<visual>
<origin xyz="0.06695440000000019154 0.088900000000000006795 -0.38290500000000005087" rpy="-3.141592653589793116 -2.0092247944502845581e-16 5.9869139995141861697e-24" />
<geometry>
<mesh filename="package:///legjointconnector4.stl"/>
</geometry>
<material name="legjointconnector4_material">
<color rgba="0.49803921568627451677 0.49803921568627451677 0.49803921568627451677 1.0"/>
</material>
</visual>
<collision>
<origin xyz="0.06695440000000019154 0.088900000000000006795 -0.38290500000000005087" rpy="-3.141592653589793116 -2.0092247944502845581e-16 5.9869139995141861697e-24" />
<geometry>
<mesh filename="package:///legjointconnector4.stl"/>
</geometry>
</collision>
<inertial>
<origin xyz="-0.45470653616358736038 -0.0064117836026284097395 -0.22961601618582527795" rpy="0 0 0"/>
<mass value="113.67855069945754565" />
<inertia ixx="2.1103224452338622541" ixy="-0.31372494572636583365"  ixz="-9.9897013474607166325e-07" iyy="8.909145154302921199" iyz="1.3223695420967730194e-07" izz="7.554349843053236313" />
</inertial>
</link>

<joint name="FR_J4" type="revolute">
<origin xyz="-1.164502402844935558 -3.1225022567582527699e-17 4.4408920985006261617e-16" rpy="-3.8581974629149813854e-14 -2.1207345775403515895e-14 -7.3163696734599736933e-14" />
<parent link="segment3_3" />
<child link="legjointconnector4_3" />
<axis xyz="0 0 1"/>
<limit effort="1" velocity="20" lower="-0.34906585039886589561" upper="1.0471975511965976313"/>
<joint_properties friction="0.0"/>
</joint>

<joint name="FR_J3" type="revolute">
<origin xyz="0.20990560000000035856 -0.25054559999999992392 0" rpy="1.1168225010396418927e-14 6.9265645206730398148e-15 -3.1415926535897149563" />
<parent link="legjointconnector2_3" />
<child link="segment3_3" />
<axis xyz="0 0 1"/>
<limit effort="1" velocity="20" lower="-0.1745329251994329478" upper="0.1745329251994329478"/>
<joint_properties friction="0.0"/>
</joint>

<joint name="FR_J2" type="revolute">
<origin xyz="-0.45577759999999978291 -0.27635199999999360276 -0.12700000000000097322" rpy="-1.570796326794896336 -1.1199904040369779026e-14 -3.1415926535897868987" />
<parent link="segment1_2" />
<child link="legjointconnector2_3" />
<axis xyz="0 0 1"/>
<limit effort="1" velocity="20" lower="-0.52359877559829881566" upper="1.3962634015954635824"/>
<joint_properties friction="0.0"/>
</joint>

<joint name="FR_J1" type="revolute">
<origin xyz="-0.59589281598084009595 0.49792200787265827877 -0.1413711901107923552" rpy="-4.1366065395598690051e-08 1.5386515297447615188e-08 -2.2689280220592671355" />
<parent link="base" />
<child link="segment1_2" />
<axis xyz="0 0 1"/>
<limit effort="1" velocity="20" lower="0" upper="0.87266462599716476678"/>
<joint_properties friction="0.0"/>
</joint>

<link name="segment1inverse_2">
<visual>
<origin xyz="-0.52245259999999960066 0.15773400000000015186 -0.27543125000000001634" rpy="-1.5707963267948970021 -1.570796326794896336 0" />
<geometry>
<mesh filename="package:///motor.stl"/>
</geometry>
<material name="motor_material">
<color rgba="0.64705882352941179736 0.64705882352941179736 0.64705882352941179736 1.0"/>
</material>
</visual>
<collision>
<origin xyz="-0.52245259999999960066 0.15773400000000015186 -0.27543125000000001634" rpy="-1.5707963267948970021 -1.570796326794896336 0" />
<geometry>
<mesh filename="package:///motor.stl"/>
</geometry>
</collision>
<visual>
<origin xyz="0.038506400000000273742 -0.088899999999999979039 -0.45923199999999997356" rpy="3.6532230084497073701e-24 -4.3107955582977604979e-25 -1.5490333779596078233e-17" />
<geometry>
<mesh filename="package:///legjointconnector1.stl"/>
</geometry>
<material name="legjointconnector1_material">
<color rgba="0.2313725490196078538 0.38039215686274507888 0.7058823529411765163 1.0"/>
</material>
</visual>
<collision>
<origin xyz="0.038506400000000273742 -0.088899999999999979039 -0.45923199999999997356" rpy="3.6532230084497073701e-24 -4.3107955582977604979e-25 -1.5490333779596078233e-17" />
<geometry>
<mesh filename="package:///legjointconnector1.stl"/>
</geometry>
</collision>
<inertial>
<origin xyz="-0.40919518440973617901 0.029508437651028437965 -0.22545957775453856486" rpy="0 0 0"/>
<mass value="188.73631876709129074" />
<inertia ixx="4.6537577933983591549" ixy="0.25943209440128722765"  ixz="0.036542406653598535904" iyy="5.7446693413348253188" iyz="-0.16661863662344705839" izz="4.0892590965830581951" />
</inertial>
</link>

<link name="legjointconnector2_4">
<visual>
<origin xyz="0.070232476114742758977 0.16024474380306930055 -0.028702000000000060798" rpy="-1.570796326794896558 1.1104646610184835504e-17 -2.1393398534388129814e-24" />
<geometry>
<mesh filename="package:///legjointconnector2.stl"/>
</geometry>
<material name="legjointconnector2_material">
<color rgba="0.76862745098039220171 0.88627450980392152857 0.95294117647058818044 1.0"/>
</material>
</visual>
<collision>
<origin xyz="0.070232476114742758977 0.16024474380306930055 -0.028702000000000060798" rpy="-1.570796326794896558 1.1104646610184835504e-17 -2.1393398534388129814e-24" />
<geometry>
<mesh filename="package:///legjointconnector2.stl"/>
</geometry>
</collision>
<inertial>
<origin xyz="0.061843433631572596043 0.16731335776010919369 -0.2295789058803080207" rpy="0 0 0"/>
<mass value="33.700879238921558567" />
<inertia ixx="1.8183343062068191287" ixy="-0.17203321537692886634"  ixz="-0.00026994432076563230644" iyy="1.7231385643804477681" iyz="-0.00019728284462274662029" izz="0.83789669946887146423" />
</inertial>
</link>

<link name="segment3_4">
<visual>
<origin xyz="-0.55685120142246136155 0.06349999999999973721 -0.47548800000000590593" rpy="-1.5338068785583921343e-15 1.5072706110722864254e-15 3.141592653589793116" />
<geometry>
<mesh filename="package:///legjointconnector3.stl"/>
</geometry>
<material name="legjointconnector3_material">
<color rgba="0.81176470588235294379 0.85882352941176465233 0.89803921568627453897 1.0"/>
</material>
</visual>
<collision>
<origin xyz="-0.55685120142246136155 0.06349999999999973721 -0.47548800000000590593" rpy="-1.5338068785583921343e-15 1.5072706110722864254e-15 3.141592653589793116" />
<geometry>
<mesh filename="package:///legjointconnector3.stl"/>
</geometry>
</collision>
<visual>
<origin xyz="-0.14843124999999990354 -0.066675000000000012035 -0.1186179999999999457" rpy="7.4105550203607828039e-24 7.8692787938278725212e-17 1.0776955463942810349e-25" />
<geometry>
<mesh filename="package:///motor.stl"/>
</geometry>
<material name="motor_material">
<color rgba="0.64705882352941179736 0.64705882352941179736 0.64705882352941179736 1.0"/>
</material>
</visual>
<collision>
<origin xyz="-0.14843124999999990354 -0.066675000000000012035 -0.1186179999999999457" rpy="7.4105550203607828039e-24 7.8692787938278725212e-17 1.0776955463942810349e-25" />
<geometry>
<mesh filename="package:///motor.stl"/>
</geometry>
</collision>
<visual>
<origin xyz="-1.0160711528449148933 0.066674999999999609579 -0.11861800000000666255" rpy="-1.5504335140662858812e-15 -3.8800779836494310806e-16 -3.141592653589793116" />
<geometry>
<mesh filename="package:///motor.stl"/>
</geometry>
<material name="motor_material">
<color rgba="0.64705882352941179736 0.64705882352941179736 0.64705882352941179736 1.0"/>
</material>
</visual>
<collision>
<origin xyz="-1.0160711528449148933 0.066674999999999609579 -0.11861800000000666255" rpy="-1.5504335140662858812e-15 -3.8800779836494310806e-16 -3.141592653589793116" />
<geometry>
<mesh filename="package:///motor.stl"/>
</geometry>
</collision>
<inertial>
<origin xyz="-0.58225120142245856414 -0.029032930571646162893 -0.24178339289668740464" rpy="0 0 0"/>
<mass value="415.11154881410027429" />
<inertia ixx="7.8602906044070337543" ixy="-7.5717210279435676057e-14"  ixz="-4.5957682104358354991e-13" iyy="82.893177179426274392" iyz="-0.12274391499224879265" izz="79.382284917837637295" />
</inertial>
</link>

<link name="legjointconnector4_4">
<visual>
<origin xyz="0.066954399999999969495 -0.088900000000000006795 -0.076326999999999811664" rpy="4.9891091087146932068e-24 -2.3394046131574057584e-17 1.1693984510961485946e-24" />
<geometry>
<mesh filename="package:///legjointconnector4.stl"/>
</geometry>
<material name="legjointconnector4_material">
<color rgba="0.49803921568627451677 0.49803921568627451677 0.49803921568627451677 1.0"/>
</material>
</visual>
<collision>
<origin xyz="0.066954399999999969495 -0.088900000000000006795 -0.076326999999999811664" rpy="4.9891091087146932068e-24 -2.3394046131574057584e-17 1.1693984510961485946e-24" />
<geometry>
<mesh filename="package:///legjointconnector4.stl"/>
</geometry>
</collision>
<inertial>
<origin xyz="-0.45470653616358758242 0.0064117836026284097395 -0.22961598381417466785" rpy="0 0 0"/>
<mass value="113.67855069945754565" />
<inertia ixx="2.1103224452338622541" ixy="0.31372494572636583365"  ixz="9.9897013469980481784e-07" iyy="8.909145154302921199" iyz="1.3223695428005102266e-07" izz="7.5543498430532345367" />
</inertial>
</link>

<joint name="BR_J4" type="revolute">
<origin xyz="-1.1645024028449151299 7.8409501114151680667e-16 -7.5495165674510644749e-15" rpy="-1.8770539177431924915e-15 6.4170359308439466523e-16 -2.2204497208545383792e-16" />
<parent link="segment3_4" />
<child link="legjointconnector4_4" />
<axis xyz="0 0 1"/>
<limit effort="1" velocity="20" lower="-1.0471975511965976313" upper="0.34906585039886589561"/>
<joint_properties friction="0.0"/>
</joint>

<joint name="BR_J3" type="revolute">
<origin xyz="0.20990560000000008101 0.25054559999999992392 -5.5511151231257827021e-17" rpy="-7.143255743244556814e-17 -7.0098970658315433197e-16 3.1415926535897775729" />
<parent link="legjointconnector2_4" />
<child link="segment3_4" />
<axis xyz="0 0 1"/>
<limit effort="1" velocity="20" lower="-0.1745329251994329478" upper="0.1745329251994329478"/>
<joint_properties friction="0.0"/>
</joint>

<joint name="BR_J2" type="revolute">
<origin xyz="-0.45577759999999961638 0.27635199999999998655 -0.12699999999999997402" rpy="1.570796326794896336 -1.4139325538541093417e-14 3.1415926535897926719" />
<parent link="segment1inverse_2" />
<child link="legjointconnector2_4" />
<axis xyz="0 0 1"/>
<limit effort="1" velocity="20" lower="-1.3962634015954635824" upper="0.52359877559829881566"/>
<joint_properties friction="0.0"/>
</joint>

<joint name="BR_J1" type="revolute">
<origin xyz="0.096795214481245284155 -0.083312256477406296251 -0.14137122751564284995" rpy="-4.1366066429508016595e-08 1.5386513625598157424e-08 -2.2689280220592662474" />
<parent link="base" />
<child link="segment1inverse_2" />
<axis xyz="0 0 1"/>
<limit effort="1" velocity="20" lower="-0.87266462599716476678" upper="0"/>
<joint_properties friction="0.0"/>
</joint>


</robot>
